Workbook

Sheet סיכום
A1: נווה יעקב – כמה עלה החומר, המתקין והיועץ
A2: כל הסכומים לא כוללים מע"מ · מקור: גיליון "נווה יעקב" (קובץ מ-15/10/2026) + עדכוני שמואל. בידוד מרפסת רוטנברג (99,716) לא נכלל – עבר דרכנו ובית ירושלמי החזיר.
A3: שטח בפועל (מ"ר): | B3: 3000
A5: סעיף | B5: עלות (₪) | C5: % מהעלות | D5: עלות למ"ר (₪)
A6: 🧱 חומר | B6: =פירוט!D32 -> 461200.77 | C6: =B6/פירוט!$D$55 -> 0.41349585 | D6: =B6/$B$3 -> 153.73359
A7: HPL – יבוא | B7: =SUMIFS(פירוט!$D$5:$D$31,פירוט!$B$5:$B$31,"HPL – יבוא") -> 379096.45 | C7: =B7/פירוט!$D$55 -> 0.3398841 | D7: =B7/$B$3 -> 126.36548
A8: קונסטרוקציה ופרופילים | B8: =SUMIFS(פירוט!$D$5:$D$31,פירוט!$B$5:$B$31,"קונסטרוקציה ופרופילים") -> 45928.32 | C8: =B8/פירוט!$D$55 -> 0.041177663 | D8: =B8/$B$3 -> 15.30944
A9: ברגים וחומרי עזר | B9: =SUMIFS(פירוט!$D$5:$D$31,פירוט!$B$5:$B$31,"ברגים וחומרי עזר") -> 24259 | C9: =B9/פירוט!$D$55 -> 0.021749738 | D9: =B9/$B$3 -> 8.0863333
A10: הובלת חומר | B10: =SUMIFS(פירוט!$D$5:$D$31,פירוט!$B$5:$B$31,"הובלת חומר") -> 11917 | C10: =B10/פירוט!$D$55 -> 0.010684349 | D10: =B10/$B$3 -> 3.9723333
A11: 👷 מתקין | B11: =פירוט!D44 -> 638919 | C11: =B11/פירוט!$D$55 -> 0.57283156 | D11: =B11/$B$3 -> 212.973
A12: קבלן מבצע – חאדר | B12: =SUMIFS(פירוט!$D$35:$D$43,פירוט!$B$35:$B$43,"קבלן מבצע – חאדר") -> 634119 | C12: =B12/פירוט!$D$55 -> 0.56852805 | D12: =B12/$B$3 -> 211.373
A13: קבלני משנה | B13: =SUMIFS(פירוט!$D$35:$D$43,פירוט!$B$35:$B$43,"קבלני משנה") -> 4800 | C13: =B13/פירוט!$D$55 -> 0.0043035056 | D13: =B13/$B$3 -> 1.6
A14: 📐 יועץ | B14: =פירוט!D48 -> 10089 | C14: =B14/פירוט!$D$55 -> 0.0090454307 | D14: =B14/$B$3 -> 3.363
A15: מהנדס | B15: =SUMIFS(פירוט!$D$47:$D$47,פירוט!$B$47:$B$47,"מהנדס") -> 10089 | C15: =B15/פירוט!$D$55 -> 0.0090454307 | D15: =B15/$B$3 -> 3.363
A16: 📎 שונות | B16: =פירוט!D53 -> 5161 | C16: =B16/פירוט!$D$55 -> 0.004627165 | D16: =B16/$B$3 -> 1.7203333
A17: מדידות | B17: =SUMIFS(פירוט!$D$51:$D$52,פירוט!$B$51:$B$52,"מדידות") -> 5000 | C17: =B17/פירוט!$D$55 -> 0.0044828183 | D17: =B17/$B$3 -> 1.6666667
A18: תוכניות | B18: =SUMIFS(פירוט!$D$51:$D$52,פירוט!$B$51:$B$52,"תוכניות") -> 161 | C18: =B18/פירוט!$D$55 -> 0.00014434675 | D18: =B18/$B$3 -> 0.053666667
A19: סה"כ עלות הפרויקט | B19: =B6+B11+B14+B16 -> 1115369.8 | C19: =B19/פירוט!$D$55 -> 1 | D19: =B19/$B$3 -> 371.78992
A21: בדיקה מול גיליון הפירוט | B21: =IF(ROUND(B19-פירוט!D55,2)=0,"✅ תואם","❌ לא תואם") -> ✅ תואם
A23: ⚠️ לבדיקה
A24: גור את שיפר – חשבונית אחת בלי סכום – לא נספרה (החומר יכול לעלות יותר).
A25: מורט – אם ה-3,409.28 הוא תשלום נוסף ולא חלק מ-10,089, עלות היועץ 13,498.28.
A26: הובלת גרייטדור 7,197 – אם תקוזז מחאדר, החומר יורד ב-7,197 והמתקין עולה באותו סכום.
A27: חאדר – בגיליון "הוצאות שאין שיוך" יש גם "סדין קאפ" 10,000 + 6,520 "תשלום חאדר בית ירושלמי" – לוודא שאינם תוספת.
A28: מדידות 5,000 – אם כולל מע"מ, העלות לפני מע"מ 4,237.29.

Sheet פירוט
A1: נווה יעקב – פירוט עלויות לפי חומר / מתקין / יועץ (לא כולל מע"מ)
A3: קבוצה | B3: תת-סעיף | C3: ספק / תיאור | D3: סכום (₪) | E3: סכום ($) | F3: הערות
A4: 🧱 חומר
A5: חומר | B5: HPL – יבוא | C5: מכולה 1 – 384.61 מ"ר | D5: 39063 | E5: 10942 | F5: Shipment 1 – Commercial Invoice
A6: חומר | B6: HPL – יבוא | C6: מכולה 2 – 991.25 מ"ר | D6: 99831 | E6: 28201 | F6: Shipment 2 – Commercial Invoice
A7: חומר | B7: HPL – יבוא | C7: מכולה 3 – 1,487.4 מ"ר | D7: 235648 | E7: 68106.41 | F7: Shipment 3 – Commercial Invoice
A8: חומר | B8: HPL – יבוא | C8: עלות מט"ח לפי 3 מכולות | D8: 4554.45
A9: חומר | B9: קונסטרוקציה ופרופילים | C9: גור את שיפר | D9: 12735.59 | F9: SI266002349
A10: חומר | B10: קונסטרוקציה ופרופילים | C10: גור את שיפר | D10: 5249 | F10: SI266003946
A11: חומר | B11: קונסטרוקציה ופרופילים | C11: גור את שיפר | D11: 18823.73
A12: חומר | B12: קונסטרוקציה ופרופילים | C12: גור את שיפר – חשבונית נוספת | F12: ⚠️ סכום לא מולא בגיליון המקור ("?")
A13: חומר | B13: קונסטרוקציה ופרופילים | C13: פרופילים DB (מילי סויסה) | D13: 9120 | F13: 03/08/2026 · 10,761.60 כולל מע"מ
A14: חומר | B14: ברגים וחומרי עזר | C14: ברגים | D14: 1455
A15: חומר | B15: ברגים וחומרי עזר | C15: ברגים | D15: 1508
A16: חומר | B16: ברגים וחומרי עזר | C16: אלקטרו סליל | D16: 392
A17: חומר | B17: ברגים וחומרי עזר | C17: אלקטרו סליל | D17: 180
A18: חומר | B18: ברגים וחומרי עזר | C18: גאלה | D18: 975
A19: חומר | B19: ברגים וחומרי עזר | C19: גאלה | D19: 1239
A20: חומר | B20: ברגים וחומרי עזר | C20: גאלה קלאסיק | D20: 2000
A21: חומר | B21: ברגים וחומרי עזר | C21: גאלה קלאסיק – ברגים | D21: 1659 | F21: 14/06/2026
A22: חומר | B22: ברגים וחומרי עזר | C22: ארפק | D22: 2763
A23: חומר | B23: ברגים וחומרי עזר | C23: ארפק די | D23: 1160 | F23: 210012492
A24: חומר | B24: ברגים וחומרי עזר | C24: ארפק | D24: 1160 | F24: 210012573
A25: חומר | B25: ברגים וחומרי עזר | C25: ארפק | D25: 4640 | F25: 210012671
A26: חומר | B26: ברגים וחומרי עזר | C26: ארפק | D26: 2320
A27: חומר | B27: ברגים וחומרי עזר | C27: רוטנברג – ספריי קצף | D27: 2808
A28: חומר | B28: הובלת חומר | C28: גרייטדור – הובלה | D28: 7197 | F28: "לקזז בסוף מחאדר" – אם יקוזז, עובר לסעיף המתקין
A29: חומר | B29: הובלת חומר | C29: משאית מגור את שיפר | D29: 1750
A30: חומר | B30: הובלת חומר | C30: הובלה מההשיקוף לפרויקט | D30: 2670
A31: חומר | B31: הובלת חומר | C31: משלוח גור + ארפק | D31: 300 | F31: ביט
A32: סה"כ חומר | D32: =SUM(D5:D31) -> 461200.77 | E32: =SUM(E5:E31) -> 107249.41
A34: 👷 מתקין
A35: מתקין | B35: קבלן מבצע – חאדר | C35: חאדר – סדין קאק | D35: 20000 | F35: 20/03/2026
A36: מתקין | B36: קבלן מבצע – חאדר | C36: חאדר | D36: 24700 | F36: 20/04/2026
A37: מתקין | B37: קבלן מבצע – חאדר | C37: חאדר – מזומן לפני פסח | D37: 95000 | F37: מזומן
A38: מתקין | B38: קבלן מבצע – חאדר | C38: חאדר (ראם משלוחים) | D38: 140000 | F38: 28/06/2026 · חאדר.pdf
A39: מתקין | B39: קבלן מבצע – חאדר | C39: חאדר (ראם משלוחים) | D39: 141353 | F39: 19/07/2026 · 91013_invoice.pdf
A40: מתקין | B40: קבלן מבצע – חאדר | C40: חאדר (משי ניהול עובדים) | D40: 125758 | F40: 23/08/2026
A41: מתקין | B41: קבלן מבצע – חאדר | C41: חאדר (משי ניהול עובדים) | D41: 87308
A42: מתקין | B42: קבלני משנה | C42: נדב איטומים | D42: 2000 | F42: הודעה מיום 28.04
...
