Workbook

Sheet דשבורד
A1: דשבורד - ישר שירותי קרקע לקבלן ולפועל בע"מ | יוני - ספטמבר 2026
A3: מדד | B3: יוני | C3: יולי | D3: אוגוסט | E3: ספטמבר
A4: מכר - עובדים זרים | B4: ='עובדים זרים - יוני'!B3 -> 707644.75 | C4: ='עובדים זרים - יולי'!B3 -> 971024.5 | D4: ='עובדים זרים - אוגוסט'!B3 -> 1047144.5 | E4: ='עובדים זרים - ספטמבר'!B3 -> 682461.5
A5: עלות מכר | B5: ='עובדים זרים - יוני'!B4 -> 590480 | C5: ='עובדים זרים - יולי'!B4 -> 795551.25 | D5: ='עובדים זרים - אוגוסט'!B4 -> 881166 | E5: ='עובדים זרים - ספטמבר'!B4 -> 569835.5
A6: רווח גולמי - עובדים זרים | B6: ='עובדים זרים - יוני'!B5 -> 117164.75 | C6: ='עובדים זרים - יולי'!B5 -> 175473.25 | D6: ='עובדים זרים - אוגוסט'!B5 -> 165978.5 | E6: ='עובדים זרים - ספטמבר'!B5 -> 112626
A7: שיעור רווח גולמי | B7: =B6/B4 -> 0.16557001 | C7: =C6/C4 -> 0.1807094 | D7: =D6/D4 -> 0.15850582 | E7: =E6/E4 -> 0.16502909
A8: רווח - דירות | B8: ='דירות - יוני'!J14 -> 32365 | C8: ='דירות - שירותי קרקע'!J15 -> 40369.99 | D8: ='דירות - אוגוסט'!J15 -> 37577.79 | E8: ='דירות - ספטמבר'!J15 -> 26829.99
A9: רווח גולמי מאוחד | B9: =B6+B8 -> 149529.75 | C9: =C6+C8 -> 215843.24 | D9: =D6+D8 -> 203556.29 | E9: =E6+E8 -> 139455.99
A10: עמלות סוכנים ולעובדים | B10: ='השוואה חודשית'!B37 -> 9626 | C10: ='השוואה חודשית'!C37 -> 8326 | D10: ='השוואה חודשית'!D37 -> 15070 | E10: ='השוואה חודשית'!E37 -> 17114
A11: הוצאות תפעוליות | B11: ='השוואה חודשית'!B38 -> 79567.48 | C11: ='השוואה חודשית'!C38 -> 68946.565 | D11: ='השוואה חודשית'!D38 -> 34801.86 | E11: ='השוואה חודשית'!E38 -> 3127
A12: רווח נקי | B12: ='השוואה חודשית'!B39 -> 60336.27 | C12: ='השוואה חודשית'!C39 -> 138570.67 | D12: ='השוואה חודשית'!D39 -> 153684.43 | E12: ='השוואה חודשית'!E39 -> 119214.99
A14: פירוט לפי לקוח - ספטמבר (ממוין לפי רווח)
A15: לקוח | B15: מכר | C15: רווח גולמי | D15: שיעור
A16: שלום ברגשטיין | B16: ='סיכום מאוחד'!C74 -> 132545 | C16: ='סיכום מאוחד'!F74 -> 30251 | D16: ='סיכום מאוחד'!G74 -> 0.22823192
A17: רמא | B17: ='סיכום מאוחד'!C76 -> 94950 | C17: ='סיכום מאוחד'!F76 -> 19414.5 | D17: ='סיכום מאוחד'!G76 -> 0.20447077
A18: אליעזר הקר אלומיניום | B18: ='סיכום מאוחד'!C77 -> 70775 | C18: ='סיכום מאוחד'!F77 -> 15186.5 | D18: ='סיכום מאוחד'!G77 -> 0.21457436
A19: גרייטדור | B19: ='סיכום מאוחד'!C75 -> 135600 | C19: ='סיכום מאוחד'!F75 -> 9115 | D19: ='סיכום מאוחד'!G75 -> 0.067219764
A20: ש.ח.נ כרמלי | B20: ='סיכום מאוחד'!C78 -> 65490 | C20: ='סיכום מאוחד'!F78 -> 7991 | D20: ='סיכום מאוחד'!G78 -> 0.12201863
A21: אחמד מצודת השלום | B21: ='סיכום מאוחד'!C80 -> 47316.5 | C21: ='סיכום מאוחד'!F80 -> 6881.25 | D21: ='סיכום מאוחד'!G80 -> 0.14543024
A22: אופיר קבלן | B22: ='סיכום מאוחד'!C79 -> 56417.5 | C22: ='סיכום מאוחד'!F79 -> 6515.5 | D22: ='סיכום מאוחד'!G79 -> 0.11548722
A23: רוטנברג | B23: ='סיכום מאוחד'!C81 -> 29337 | C23: ='סיכום מאוחד'!F81 -> 3010 | D23: ='סיכום מאוחד'!G81 -> 0.10260081
A24: שי רם חברה לבנייה | B24: ='סיכום מאוחד'!C83 -> 13898.5 | C24: ='סיכום מאוחד'!F83 -> 2256.25 | D24: ='סיכום מאוחד'!G83 -> 0.16233766
A25: ארי שבט בנימין | B25: ='סיכום מאוחד'!C82 -> 16247 | C25: ='סיכום מאוחד'!F82 -> 1837.5 | D25: ='סיכום מאוחד'!G82 -> 0.1130978
A26: אלי אביאלי | B26: ='סיכום מאוחד'!C84 -> 13340 | C26: ='סיכום מאוחד'!F84 -> 1305 | D26: ='סיכום מאוחד'!G84 -> 0.097826087
A27: אסף תאגיד השידור | B27: ='סיכום מאוחד'!C85 -> 6545 | C27: ='סיכום מאוחד'!F85 -> 662.5 | D27: ='סיכום מאוחד'!G85 -> 0.10122231
A30: מקרא: שיעור רווח מתחת ל-10% מסומן באדום. הדשבורד מתעדכן אוטומטית מהגיליונות - אין צורך לעדכן אותו ידנית.

Sheet עובדים זרים - ספטמבר
A1: עלות מכר ורווח גולמי - עובדים זרים - ספטמבר
A3: סה"כ מכר (₪) | B3: =SUM(H9:H58) -> 682461.5
A4: סה"כ עלות מכר (₪) | B4: =SUM(I9:I58) -> 569835.5
A5: רווח גולמי (₪) | B5: =B3-B4 -> 112626
A6: שיעור רווח גולמי (%) | B6: =B5/B3 -> 0.16502909
D7: מקרא: | E7: 230 | F7: עובד שעבד פחות מ-230 שעות בחודש (חודש חלקי)
A8: מעסיק | B8: עובד | C8: שעות בפועל | D8: עלות מול תאגיד (₪/שעה) | E8: עלות גבייה שלנו (₪/שעה) | F8: דירת לינה | G8: ניכוי לינה (₪) | H8: הכנסה (₪) | I8: עלות מכר (₪) | J8: רווח גולמי (₪) | K8: הערות | L8: עמלה לעובד (₪/שעה) | M8: סה"כ עמלה לעובד (₪) | N8: עמלת גבריאל לניאדו (₪/שעה) | O8: סה"כ עמלת גבריאל (₪)
A9: רמא | B9: shuhrok | C9: 195 | D9: 83 | E9: 105 | F9: יושן בדירה שלנו בק.ג | G9: 1180 | H9: =IF(C9="","",C9*E9) -> 20475 | I9: =IF(C9="","",C9*D9) -> 16185 | J9: =IF(C9="","",H9-I9) -> 4290
A10: רמא | B10: erkin | C10: 193 | D10: 83 | E10: 100 | F10: יושנים באתר של החברה | G10: 0 | H10: =IF(C10="","",C10*E10) -> 19300 | I10: =IF(C10="","",C10*D10) -> 16019 | J10: =IF(C10="","",H10-I10) -> 3281
A11: רמא | B11: daler | C11: 199 | D11: 75 | E11: 100 | F11: יושנים באתר של החברה | G11: 0 | H11: =IF(C11="","",C11*E11) -> 19900 | I11: =IF(C11="","",C11*D11) -> 14925 | J11: =IF(C11="","",H11-I11) -> 4975
A12: רמא | B12: nodir | C12: 201 | D12: 81.5 | E12: 100 | F12: יושנים באתר של החברה | G12: 0 | H12: =IF(C12="","",C12*E12) -> 20100 | I12: =IF(C12="","",C12*D12) -> 16381.5 | J12: =IF(C12="","",H12-I12) -> 3718.5
A13: רמא | B13: dmitri | C13: 31 | D13: 80 | E13: 100 | F13: יושנים באתר של החברה | G13: 0 | H13: =IF(C13="","",C13*E13) -> 3100 | I13: =IF(C13="","",C13*D13) -> 2480 | J13: =IF(C13="","",H13-I13) -> 620
A14: רמא | B14: azamat | C14: 115 | D14: 83 | E14: 105 | F14: יושן בדירה שלנו בק.ג | G14: 1180 | H14: =IF(C14="","",C14*E14) -> 12075 | I14: =IF(C14="","",C14*D14) -> 9545 | J14: =IF(C14="","",H14-I14) -> 2530
A15: גרייטדור | B15: ranjith | C15: 157.5 | D15: 70 | E15: 75 | F15: שער בנימין | G15: 0 | H15: =IF(C15="","",C15*E15) -> 11812.5 | I15: =IF(C15="","",C15*D15) -> 11025 | J15: =IF(C15="","",H15-I15) -> 787.5
A16: גרייטדור | B16: dinoka | C16: 153.5 | D16: 70 | E16: 75 | F16: שער בנימין | G16: 0 | H16: =IF(C16="","",C16*E16) -> 11512.5 | I16: =IF(C16="","",C16*D16) -> 10745 | J16: =IF(C16="","",H16-I16) -> 767.5
A17: גרייטדור | B17: susitha | C17: 183 | D17: 70 | E17: 75 | F17: שער בנימין | G17: 0 | H17: =IF(C17="","",C17*E17) -> 13725 | I17: =IF(C17="","",C17*D17) -> 12810 | J17: =IF(C17="","",H17-I17) -> 915
A18: גרייטדור | B18: Suresh | C18: 153.5 | D18: 70 | E18: 75 | F18: שער בנימין | G18: 0 | H18: =IF(C18="","",C18*E18) -> 11512.5 | I18: =IF(C18="","",C18*D18) -> 10745 | J18: =IF(C18="","",H18-I18) -> 767.5
A19: גרייטדור | B19: Liyana | C19: 173.5 | D19: 70 | E19: 75 | F19: שער בנימין | G19: 0 | H19: =IF(C19="","",C19*E19) -> 13012.5 | I19: =IF(C19="","",C19*D19) -> 12145 | J19: =IF(C19="","",H19-I19) -> 867.5
A20: גרייטדור | B20: Kamal | C20: 164.5 | D20: 70 | E20: 75 | F20: שער בנימין | G20: 0 | H20: =IF(C20="","",C20*E20) -> 12337.5 | I20: =IF(C20="","",C20*D20) -> 11515 | J20: =IF(C20="","",H20-I20) -> 822.5
A21: גרייטדור | B21: rishan | C21: 68 | D21: 70 | E21: 75 | F21: שער בנימין | G21: 0 | H21: =IF(C21="","",C21*E21) -> 5100 | I21: =IF(C21="","",C21*D21) -> 4760 | J21: =IF(C21="","",H21-I21) -> 340 | K21: פסגת ליאם. בוטל במהלך החודש | N21: 1.5 | O21: =IF(C21="","",C21*N21) -> 102
A22: גרייטדור | B22: Nilanth | C22: 85 | D22: 70 | E22: 75 | F22: שער בנימין | G22: 0 | H22: =IF(C22="","",C22*E22) -> 6375 | I22: =IF(C22="","",C22*D22) -> 5950 | J22: =IF(C22="","",H22-I22) -> 425 | K22: פסגת ליאם. בוטל במהלך החודש | N22: 1.5 | O22: =IF(C22="","",C22*N22) -> 127.5
A23: גרייטדור | B23: lalith | C23: 166 | D23: 68 | E23: 75 | F23: בני ברק | G23: 0 | H23: =IF(C23="","",C23*E23) -> 12450 | I23: =IF(C23="","",C23*D23) -> 11288 | J23: =IF(C23="","",H23-I23) -> 1162 | K23: שרף | N23: 1.5 | O23: =IF(C23="","",C23*N23) -> 249
A24: גרייטדור | B24: priyantha | C24: 187.5 | D24: 68 | E24: 75 | F24: בני ברק | G24: 0 | H24: =IF(C24="","",C24*E24) -> 14062.5 | I24: =IF(C24="","",C24*D24) -> 12750 | J24: =IF(C24="","",H24-I24) -> 1312.5 | K24: שרף | N24: 1.5 | O24: =IF(C24="","",C24*N24) -> 281.25
A25: גרייטדור | B25: Randika | C25: 157 | D25: 72 | E25: 75 | F25: בני ברק | G25: 0 | H25: =IF(C25="","",C25*E25) -> 11775 | I25: =IF(C25="","",C25*D25) -> 11304 | J25: =IF(C25="","",H25-I25) -> 471 | K25: ד.יוחאי | N25: 1.5 | O25: =IF(C25="","",C25*N25) -> 235.5
A26: גרייטדור | B26: Vidura | C26: 159 | D26: 72 | E26: 75 | F26: בני ברק | G26: 0 | H26: =IF(C26="","",C26*E26) -> 11925 | I26: =IF(C26="","",C26*D26) -> 11448 | J26: =IF(C26="","",H26-I26) -> 477 | K26: ד.יוחאי | N26: 1.5 | O26: =IF(C26="","",C26*N26) -> 238.5
A27: שלום ברגשטיין | B27: heera | C27: 160 | D27: 70 | E27: 73 | F27: רחביה | G27: 0 | H27: =IF(C27="","",C27*E27) -> 11680 | I27: =IF(C27="","",C27*D27) -> 11200 | J27: =IF(C27="","",H27-I27) -> 480
A28: שלום ברגשטיין | B28: Suresh | C28: 160 | D28: 70 | E28: 73 | F28: רחביה | G28: 0 | H28: =IF(C28="","",C28*E28) -> 11680 | I28: =IF(C28="","",C28*D28) -> 11200 | J28: =IF(C28="","",H28-I28) -> 480
A29: שלום ברגשטיין | B29: sanat | C29: 34.5 | D29: 73 | E29: 90 | F29: יוסף | G29: 0 | H29: =IF(C29="","",C29*E29) -> 3105 | I29: =IF(C29="","",C29*D29) -> 2518.5 | J29: =IF(C29="","",H29-I29) -> 586.5 | K29: עבר ב-3 לחודש לאליעזר הקר - הלינה מחויבת שם
A30: שלום ברגשטיין | B30: damir | C30: 182.5 | D30: 73 | E30: 90 | F30: יוסף | G30: 1180 | H30: =IF(C30="","",C30*E30) -> 16425 | I30: =IF(C30="","",C30*D30) -> 13322.5 | J30: =IF(C30="","",H30-I30) -> 3102.5
A31: שלום ברגשטיין | B31: djamol | C31: 169 | D31: 73 | E31: 90 | F31: יוסף | G31: 1180 | H31: =IF(C31="","",C31*E31) -> 15210 | I31: =IF(C31="","",C31*D31) -> 12337 | J31: =IF(C31="","",H31-I31) -> 2873
A32: שלום ברגשטיין | B32: khasanjon | C32: 177 | D32: 72 | E32: 105 | F32: בית חנינה | G32: 1180 | H32: =IF(C32="","",C32*E32) -> 18585 | I32: =IF(C32="","",C32*D32) -> 12744 | J32: =IF(C32="","",H32-I32) -> 5841 | K32: פניני התכלת. בוטל | N32: 1.5 | O32: =IF(C32="","",C32*N32) -> 265.5
A33: שלום ברגשטיין | B33: maruf | C33: 178 | D33: 71 | E33: 105 | F33: בית חנינה | G33: 1180 | H33: =IF(C33="","",C33*E33) -> 18690 | I33: =IF(C33="","",C33*D33) -> 12638 | J33: =IF(C33="","",H33-I33) -> 6052 | K33: שי-לי | N33: 1.5 | O33: =IF(C33="","",C33*N33) -> 267
A34: שלום ברגשטיין | B34: tukhtamurod | C34: 175 | D34: 71 | E34: 105 | F34: בית חנינה | G34: 1180 | H34: =IF(C34="","",C34*E34) -> 18375 | I34: =IF(C34="","",C34*D34) -> 12425 | J34: =IF(C34="","",H34-I34) -> 5950 | K34: שי-לי. בוטל | N34: 1.5 | O34: =IF(C34="","",C34*N34) -> 262.5
A35: שלום ברגשטיין | B35: khurshed | C35: 179 | D35: 71 | E35: 105 | F35: בית חנינה | G35: 1180 | H35: =IF(C35="","",C35*E35) -> 18795 | I35: =IF(C35="","",C35*D35) -> 12709 | J35: =IF(C35="","",H35-I35) -> 6086 | K35: שי-לי | N35: 1.5 | O35: =IF(C35="","",C35*N35) -> 268.5
A36: אלי אביאלי | B36: Vasile | C36: 145 | D36: 83 | E36: 92 | F36: דירה של התאגיד | G36: 0 | H36: =IF(C36="","",C36*E36) -> 13340 | I36: =IF(C36="","",C36*D36) -> 12035 | J36: =IF(C36="","",H36-I36) -> 1305
A37: אחמד מצודת השלום | B37: parimol | C37: 139 | D37: 64.5 | E37: 77 | F37: קארו | G37: 1180 | H37: =IF(C37="","",C37*E37) -> 10703 | I37: =IF(C37="","",C37*D37) -> 8965.5 | J37: =IF(C37="","",H37-I37) -> 1737.5 | K37: רועי: 2 ₪ נוספים לכל שעת עבודה + 100 ₪ למיטה
A38: אחמד מצודת השלום | B38: kumar | C38: 156.5 | D38: 64.5 | E38: 77 | F38: קארו | G38: 1180 | H38: =IF(C38="","",C38*E38) -> 12050.5 | I38: =IF(C38="","",C38*D38) -> 10094.25 | J38: =IF(C38="","",H38-I38) -> 1956.25 | K38: רועי: 2 ₪ נוספים לכל שעת עבודה + 100 ₪ למיטה
A39: אחמד מצודת השלום | B39: sanjay | C39: 154.5 | D39: 64.5 | E39: 77 | F39: קארו | G39: 1180 | H39: =IF(C39="","",C39*E39) -> 11896.5 | I39: =IF(C39="","",C39*D39) -> 9965.25 | J39: =IF(C39="","",H39-I39) -> 1931.25
A40: אחמד מצודת השלום | B40: harikesh | C40: 164.5 | D40: 64.5 | E40: 77 | F40: קארו | G40: 1180 | H40: =IF(C40="","",C40*E40) -> 12666.5 | I40: =IF(C40="","",C40*D40) -> 10610.25 | J40: =IF(C40="","",H40-I40) -> 2056.25
A41: אופיר קבלן | B41: samandar | C41: 130.5 | D41: 78 | E41: 90 | F41: בני ברק | G41: 0 | H41: =IF(C41="","",C41*E41) -> 11745 | I41: =IF(C41="","",C41*D41) -> 10179 | J41: =IF(C41="","",H41-I41) -> 1566 | K41: 2 נוסף מאיתנו | L41: 2 | M41: =IF(C41="","",C41*L41) -> 261
...

Sheet עובדים זרים - אוגוסט
A1: עלות מכר ורווח גולמי - עובדים זרים - אוגוסט
A3: סה"כ מכר (₪) | B3: =SUM(H9:H67) -> 1047144.5
A4: סה"כ עלות מכר (₪) | B4: =SUM(I9:I67) -> 881166
A5: רווח גולמי (₪) | B5: =B3-B4 -> 165978.5
A6: שיעור רווח גולמי (%) | B6: =B5/B3 -> 0.15850582
D7: מקרא: | E7: 230 | F7: עובד שעבד פחות מ-230 שעות בחודש (חודש חלקי)
A8: מעסיק | B8: עובד | C8: שעות בפועל | D8: עלות מול תאגיד (₪/שעה) | E8: עלות גבייה שלנו (₪/שעה) | F8: דירת לינה | G8: ניכוי לינה (₪) | H8: הכנסה (₪) | I8: עלות מכר (₪) | J8: רווח גולמי (₪) | K8: הערות | L8: עמלה לעובד (₪/שעה) | M8: סה"כ עמלה לעובד (₪)
A9: רמא | B9: shuhrok | C9: 221 | D9: 77 | E9: 105 | F9: יושן בדירה שלנו בק.ג | G9: 1180 | H9: =IF(C9="","",C9*E9) -> 23205 | I9: =IF(C9="","",C9*D9) -> 17017 | J9: =IF(C9="","",H9-I9) -> 6188
A10: רמא | B10: erkin | C10: 238 | D10: 83 | E10: 100 | F10: יושנים באתר של החברה | G10: 0 | H10: =IF(C10="","",C10*E10) -> 23800 | I10: =IF(C10="","",C10*D10) -> 19754 | J10: =IF(C10="","",H10-I10) -> 4046
A11: רמא | B11: daler | C11: 32 | D11: 75 | E11: 100 | F11: יושנים באתר של החברה | G11: 0 | H11: =IF(C11="","",C11*E11) -> 3200 | I11: =IF(C11="","",C11*D11) -> 2400 | J11: =IF(C11="","",H11-I11) -> 800
A12: רמא | B12: nodir | C12: 270 | D12: 82 | E12: 100 | F12: יושנים באתר של החברה | G12: 0 | H12: =IF(C12="","",C12*E12) -> 27000 | I12: =IF(C12="","",C12*D12) -> 22140 | J12: =IF(C12="","",H12-I12) -> 4860
A13: רמא | B13: dmitri | C13: 221 | D13: 80 | E13: 100 | F13: יושן בדירה שלנו בק.ג | G13: 1180 | H13: =IF(C13="","",C13*E13) -> 22100 | I13: =IF(C13="","",C13*D13) -> 17680 | J13: =IF(C13="","",H13-I13) -> 4420
A14: רמא | B14: azamat | C14: 99 | D14: 83 | E14: 105 | F14: יושן בדירה שלנו בק.ג | G14: 1180 | H14: =IF(C14="","",C14*E14) -> 10395 | I14: =IF(C14="","",C14*D14) -> 8217 | J14: =IF(C14="","",H14-I14) -> 2178
A15: גרייטדור | B15: ranjith | C15: 253 | D15: 70 | E15: 75 | F15: שער בנימין | G15: 0 | H15: =IF(C15="","",C15*E15) -> 18975 | I15: =IF(C15="","",C15*D15) -> 17710 | J15: =IF(C15="","",H15-I15) -> 1265
A16: גרייטדור | B16: dinoka | C16: 211.5 | D16: 70 | E16: 75 | F16: שער בנימין | G16: 0 | H16: =IF(C16="","",C16*E16) -> 15862.5 | I16: =IF(C16="","",C16*D16) -> 14805 | J16: =IF(C16="","",H16-I16) -> 1057.5
A17: גרייטדור | B17: susitha | C17: 267.5 | D17: 70 | E17: 75 | F17: שער בנימין | G17: 0 | H17: =IF(C17="","",C17*E17) -> 20062.5 | I17: =IF(C17="","",C17*D17) -> 18725 | J17: =IF(C17="","",H17-I17) -> 1337.5
A18: גרייטדור | B18: Suresh | C18: 240.5 | D18: 70 | E18: 75 | F18: שער בנימין | G18: 0 | H18: =IF(C18="","",C18*E18) -> 18037.5 | I18: =IF(C18="","",C18*D18) -> 16835 | J18: =IF(C18="","",H18-I18) -> 1202.5
A19: גרייטדור | B19: Liyana | C19: 266 | D19: 70 | E19: 75 | F19: שער בנימין | G19: 0 | H19: =IF(C19="","",C19*E19) -> 19950 | I19: =IF(C19="","",C19*D19) -> 18620 | J19: =IF(C19="","",H19-I19) -> 1330
A20: גרייטדור | B20: Kamal | C20: 238.5 | D20: 70 | E20: 75 | F20: שער בנימין | G20: 0 | H20: =IF(C20="","",C20*E20) -> 17887.5 | I20: =IF(C20="","",C20*D20) -> 16695 | J20: =IF(C20="","",H20-I20) -> 1192.5
... A41: אלי אביאלי | B41: sanjar | C41: 178 | D41: 81 | E41: 92 | F41: דירה של התאגיד | G41: 0 | H41: =IF(C41="","",C41*E41) -> 16376 | I41: =IF(C41="","",C41*D41) -> 14418 | J41: =IF(C41="","",H41-I41) -> 1958
A42: אחמד מצודת השלום | B42: parimol | C42: 255 | D42: 64.5 | E42: 77 | F42: קארו | G42: 1180 | H42: =IF(C42="","",C42*E42) -> 19635 | I42: =IF(C42="","",C42*D42) -> 16447.5 | J42: =IF(C42="","",H42-I42) -> 3187.5 | K42: רועי: 2 ₪ נוספים לכל שעת עבודה + 100 ₪ למיטה
A43: אחמד מצודת השלום | B43: kumar | C43: 244 | D43: 64.5 | E43: 77 | F43: קארו | G43: 1180 | H43: =IF(C43="","",C43*E43) -> 18788 | I43: =IF(C43="","",C43*D43) -> 15738 | J43: =IF(C43="","",H43-I43) -> 3050 | K43: רועי: 2 ₪ נוספים לכל שעת עבודה + 100 ₪ למיטה (יתרה לתשלום 13.575)
A44: אחמד מצודת השלום | B44: sanjay | C44: 254 | D44: 64.5 | E44: 77 | F44: קארו | G44: 1180 | H44: =IF(C44="","",C44*E44) -> 19558 | I44: =IF(C44="","",C44*D44) -> 16383 | J44: =IF(C44="","",H44-I44) -> 3175
A45: אחמד מצודת השלום | B45: harikesh | C45: 254 | D45: 64.5 | E45: 77 | F45: קארו | G45: 1180 | H45: =IF(C45="","",C45*E45) -> 19558 | I45: =IF(C45="","",C45*D45) -> 16383 | J45: =IF(C45="","",H45-I45) -> 3175
A46: אופיר קבלן | B46: samandar | C46: 236 | D46: 78 | E46: 90 | F46: בני ברק | G46: 0 | H46: =IF(C46="","",C46*E46) -> 21240 | I46: =IF(C46="","",C46*D46) -> 18408 | J46: =IF(C46="","",H46-I46) -> 2832 | K46: 2 נוסף מאיתנו (להשלים 12 שעות) | L46: 2 | M46: =IF(C46="","",C46*L46) -> 472
A47: אופיר קבלן | B47: akmal | C47: 257.5 | D47: 78 | E47: 90 | F47: בני ברק | G47: 0 | H47: =IF(C47="","",C47*E47) -> 23175 | I47: =IF(C47="","",C47*D47) -> 20085 | J47: =IF(C47="","",H47-I47) -> 3090 | K47: 2 נוסף מאיתנו ( להשלים 11 שעות) | L47: 2 | M47: =IF(C47="","",C47*L47) -> 515
A48: אופיר קבלן | B48: Farkhod | C48: 256 | D48: 78 | E48: 95 | F48: בני ברק | G48: 0 | H48: =IF(C48="","",C48*E48) -> 24320 | I48: =IF(C48="","",C48*D48) -> 19968 | J48: =IF(C48="","",H48-I48) -> 4352 | K48: 2 נוסף מאיתנו | L48: 2 | M48: =IF(C48="","",C48*L48) -> 512
A49: אופיר קבלן | B49: Rustam | C49: 266.5 | D49: 78 | E49: 95 | F49: בני ברק | G49: 0 | H49: =IF(C49="","",C49*E49) -> 25317.5 | I49: =IF(C49="","",C49*D49) -> 20787 | J49: =IF(C49="","",H49-I49) -> 4530.5 | K49: 2 נוסף מאיתנו | L49: 2 | M49: =IF(C49="","",C49*L49) -> 533
A50: מאי מערכות חשמל | B50: welikala | C50: 139.5 | D50: 70 | E50: 77 | F50: אצל התאגיד | G50: 0 | H50: =IF(C50="","",C50*E50) -> 10741.5 | I50: =IF(C50="","",C50*D50) -> 9765 | J50: =IF(C50="","",H50-I50) -> 976.5
A51: אליעזר הקר אלומיניום | B51: murod | C51: 267.5 | D51: 73.5 | E51: 95 | F51: בית חנינה | G51: 1180 | H51: =IF(C51="","",C51*E51) -> 25412.5 | I51: =IF(C51="","",C51*D51) -> 19661.25 | J51: =IF(C51="","",H51-I51) -> 5751.25
A52: אליעזר הקר אלומיניום | B52: odil | C52: 267 | D52: 73.5 | E52: 95 | F52: בית חנינה | G52: 1180 | H52: =IF(C52="","",C52*E52) -> 25365 | I52: =IF(C52="","",C52*D52) -> 19624.5 | J52: =IF(C52="","",H52-I52) -> 5740.5
A53: אליעזר הקר אלומיניום | B53: temurbek | C53: 44 | D53: 73.5 | E53: 95 | F53: בית חנינה | G53: 1180 | H53: =IF(C53="","",C53*E53) -> 4180 | I53: =IF(C53="","",C53*D53) -> 3234 | J53: =IF(C53="","",H53-I53) -> 946
A54: אליעזר הקר אלומיניום | B54: SAMANDAR | C54: 22 | D54: 36 | E54: 50 | G54: 0 | H54: =IF(C54="","",C54*E54) -> 1100 | I54: =IF(C54="","",C54*D54) -> 792 | J54: =IF(C54="","",H54-I54) -> 308 | K54: עובד בניסיון
A55: אסף תאגיד השידור | B55: nagendra | C55: 216 | D55: 64.5 | E55: 77 | F55: קארו | G55: 1180 | H55: =IF(C55="","",C55*E55) -> 16632 | I55: =IF(C55="","",C55*D55) -> 13932 | J55: =IF(C55="","",H55-I55) -> 2700
A56: אסף תאגיד השידור | B56: Praveen | C56: 39 | D56: 64.5 | E56: 77 | F56: קארו | G56: 1180 | H56: =IF(C56="","",C56*E56) -> 3003 | I56: =IF(C56="","",C56*D56) -> 2515.5 | J56: =IF(C56="","",H56-I56) -> 487.5
A57: ארי שבט בנימין | B57: sri ram | C57: 137 | D57: 66.5 | E57: 77 | F57: קארו | G57: 1180 | H57: =IF(C57="","",C57*E57) -> 10549 | I57: =IF(C57="","",C57*D57) -> 9110.5 | J57: =IF(C57="","",H57-I57) -> 1438.5
A58: ארי שבט בנימין | B58: Praveen | C58: 138 | D58: 64.5 | E58: 77 | F58: קארו | G58: 1180 | H58: =IF(C58="","",C58*E58) -> 10626 | I58: =IF(C58="","",C58*D58) -> 8901 | J58: =IF(C58="","",H58-I58) -> 1725
A59: ש.ח.נ כרמלי | B59: andrei | C59: 258 | D59: 73 | E59: 90 | F59: בת ים | G59: 0 | H59: =IF(C59="","",C59*E59) -> 23220 | I59: =IF(C59="","",C59*D59) -> 18834 | J59: =IF(C59="","",H59-I59) -> 4386 | K59: תוספת 10 ₪ מאיתנו | L59: 10 | M59: =IF(C59="","",C59*L59) -> 2580
A60: ש.ח.נ כרמלי | B60: alexandr | C60: 252 | D60: 73 | E60: 85 | F60: בת ים | G60: 0 | H60: =IF(C60="","",C60*E60) -> 21420 | I60: =IF(C60="","",C60*D60) -> 18396 | J60: =IF(C60="","",H60-I60) -> 3024 | K60: תוספת 5 ₪ מאיתנו (זיכוי נעה 17,739) | L60: 5 | M60: =IF(C60="","",C60*L60) -> 1260
A61: ש.ח.נ כרמלי | B61: abdurauf | C61: 253 | D61: 73 | E61: 85 | F61: פתח תקווה | G61: 0 | H61: =IF(C61="","",C61*E61) -> 21505 | I61: =IF(C61="","",C61*D61) -> 18469 | J61: =IF(C61="","",H61-I61) -> 3036 | K61: להתקזז על דלק בחשבונית 1611 שח
...

Sheet עובדים זרים - יולי
A1: עלות מכר ורווח גולמי - עובדים זרים - יולי
A3: סה"כ מכר (₪) | B3: =H75 -> 971024.5
A4: סה"כ עלות מכר (₪) | B4: =I75 -> 795551.25
A5: רווח גולמי (₪) | B5: =B3-B4 -> 175473.25
A6: שיעור רווח גולמי (%) | B6: =B5/B3 -> 0.1807094
D7: מקרא: | E7: 230 | F7: עובד שעבד פחות מ-230 שעות בחודש (חודש חלקי)
A8: מעסיק | B8: עובד | C8: שעות בפועל | D8: עלות מול תאגיד (₪/שעה) | E8: עלות גבייה שלנו (₪/שעה) | F8: דירת לינה | G8: ניכוי לינה (₪) | H8: הכנסה (₪) | I8: עלות מכר (₪) | J8: רווח גולמי (₪)
A9: אופיר קבלן | B9: akmal | C9: 231 | D9: 78 | E9: 90 | G9: 0 | H9: =C9*E9 -> 20790 | I9: =C9*D9 -> 18018 | J9: =H9-I9 -> 2772
A10: אופיר קבלן | B10: Farkhod | C10: 246 | D10: 78 | E10: 95 | G10: 0 | H10: =C10*E10 -> 23370 | I10: =C10*D10 -> 19188 | J10: =H10-I10 -> 4182
A11: אופיר קבלן | B11: Rustam | C11: 248.5 | D11: 78 | E11: 95 | G11: 0 | H11: =C11*E11 -> 23607.5 | I11: =C11*D11 -> 19383 | J11: =H11-I11 -> 4224.5
A12: אופיר קבלן | B12: samandar | C12: 231.5 | D12: 78 | E12: 90 | G12: 0 | H12: =C12*E12 -> 20835 | I12: =C12*D12 -> 18057 | J12: =H12-I12 -> 2778
A13: אחמד מצודת השלום | B13: Avanish | C13: 66 | D13: 0 | E13: 77 | F13: קארו 11 | G13: 1180 | H13: =C13*E13 -> 5082 | I13: =C13*D13 -> 0 | J13: =H13-I13 -> 5082
A14: אחמד מצודת השלום | B14: harikesh | C14: 242 | D14: 64.5 | E14: 77 | F14: קארו 7 | G14: 1180 | H14: =C14*E14 -> 18634 | I14: =C14*D14 -> 15609 | J14: =H14-I14 -> 3025
A15: אחמד מצודת השלום | B15: kumar | C15: 220 | D15: 64.5 | E15: 77 | F15: קארו 7 | G15: 1180 | H15: =C15*E15 -> 16940 | I15: =C15*D15 -> 14190 | J15: =H15-I15 -> 2750
A16: אחמד מצודת השלום | B16: parimol | C16: 243 | D16: 64.5 | E16: 77 | F16: קארו 7 | G16: 1180 | H16: =C16*E16 -> 18711 | I16: =C16*D16 -> 15673.5 | J16: =H16-I16 -> 3037.5
A17: אחמד מצודת השלום | B17: ramishwar | C17: 83 | D17: 64.5 | E17: 77 | F17: קארו 11 | G17: 1180 | H17: =C17*E17 -> 6391 | I17: =C17*D17 -> 5353.5 | J17: =H17-I17 -> 1037.5
A18: אחמד מצודת השלום | B18: Roshan | C18: 60 | D18: 0 | E18: 77 | F18: קארו 11 | G18: 1180 | H18: =C18*E18 -> 4620 | I18: =C18*D18 -> 0 | J18: =H18-I18 -> 4620
A19: אחמד מצודת השלום | B19: sanjay | C19: 226 | D19: 64.5 | E19: 77 | F19: קארו 7 | G19: 1180 | H19: =C19*E19 -> 17402 | I19: =C19*D19 -> 14577 | J19: =H19-I19 -> 2825
A20: אחמד מצודת השלום | B20: sri ram | C20: 81 | D20: 64.5 | E20: 77 | F20: קארו 11 | G20: 1180 | H20: =C20*E20 -> 6237 | I20: =C20*D20 -> 5224.5 | J20: =H20-I20 -> 1012.5
A21: אלי אביאלי | B21: Asatillo | C21: 53 | D21: 81 | E21: 92 | G21: 0 | H21: =C21*E21 -> 4876 | I21: =C21*D21 -> 4293 | J21: =H21-I21 -> 583
A22: אלי אביאלי | B22: sanjar | C22: 204 | D22: 81 | E22: 92 | G22: 0 | H22: =C22*E22 -> 18768 | I22: =C22*D22 -> 16524 | J22: =H22-I22 -> 2244
A23: אלי אביאלי | B23: Vasile | C23: 209 | D23: 83 | E23: 92 | G23: 0 | H23: =C23*E23 -> 19228 | I23: =C23*D23 -> 17347 | J23: =H23-I23 -> 1881
A24: אליעזר הקר אלומיניום | B24: murod | C24: 45 | D24: 73.5 | E24: 95 | F24: בית חנינה | G24: 1180 | H24: =C24*E24 -> 4275 | I24: =C24*D24 -> 3307.5 | J24: =H24-I24 -> 967.5
A25: אליעזר הקר אלומיניום | B25: odil | C25: 45 | D25: 73.5 | E25: 95 | F25: בית חנינה | G25: 1180 | H25: =C25*E25 -> 4275 | I25: =C25*D25 -> 3307.5 | J25: =H25-I25 -> 967.5
A26: אסף תאגיד השידור | B26: nagendra | C26: 205 | D26: 64.5 | E26: 75 | F26: קארו 7 | G26: 1180 | H26: =C26*E26 -> 15375 | I26: =C26*D26 -> 13222.5 | J26: =H26-I26 -> 2152.5
A27: אסף תאגיד השידור | B27: Praveen | C27: 205 | D27: 64.5 | E27: 75 | F27: קארו 7 | G27: 1180 | H27: =C27*E27 -> 15375 | I27: =C27*D27 -> 13222.5 | J27: =H27-I27 -> 2152.5
A28: גרייטדור | B28: dinoka | C28: 259 | D28: 70 | E28: 75 | G28: 0 | H28: =C28*E28 -> 19425 | I28: =C28*D28 -> 18130 | J28: =H28-I28 -> 1295
A29: גרייטדור | B29: Kamal | C29: 241 | D29: 70 | E29: 75 | G29: 0 | H29: =C29*E29 -> 18075 | I29: =C29*D29 -> 16870 | J29: =H29-I29 -> 1205
A30: גרייטדור | B30: Liyana | C30: 290.5 | D30: 70 | E30: 75 | G30: 0 | H30: =C30*E30 -> 21787.5 | I30: =C30*D30 -> 20335 | J30: =H30-I30 -> 1452.5
A31: גרייטדור | B31: Nilanth | C31: 109 | D31: 71.5 | E31: 75 | G31: 0 | H31: =C31*E31 -> 8175 | I31: =C31*D31 -> 7793.5 | J31: =H31-I31 -> 381.5
A32: גרייטדור | B32: ranjith | C32: 292.5 | D32: 70 | E32: 75 | G32: 0 | H32: =C32*E32 -> 21937.5 | I32: =C32*D32 -> 20475 | J32: =H32-I32 -> 1462.5
A33: גרייטדור | B33: rishan | C33: 98 | D33: 71.5 | E33: 75 | G33: 0 | H33: =C33*E33 -> 7350 | I33: =C33*D33 -> 7007 | J33: =H33-I33 -> 343
A34: גרייטדור | B34: Suresh | C34: 235 | D34: 70 | E34: 75 | G34: 0 | H34: =C34*E34 -> 17625 | I34: =C34*D34 -> 16450 | J34: =H34-I34 -> 1175
A35: גרייטדור | B35: susitha | C35: 275 | D35: 70 | E35: 75 | G35: 0 | H35: =C35*E35 -> 20625 | I35: =C35*D35 -> 19250 | J35: =H35-I35 -> 1375
A36: גרשון | B36: welikala | C36: 210 | D36: 65 | E36: 77 | G36: 0 | H36: =C36*E36 -> 16170 | I36: =C36*D36 -> 13650 | J36: =H36-I36 -> 2520
A37: דוד בן חמו קבלן | B37: Akmal | C37: 87 | D37: 70 | E37: 95 | F37: קארו 3 | G37: 1180 | H37: =C37*E37 -> 8265 | I37: =C37*D37 -> 6090 | J37: =H37-I37 -> 2175
A38: דוד בן חמו קבלן | B38: bogir | C38: 52 | D38: 71 | E38: 95 | F38: קארו 3 | G38: 1180 | H38: =C38*E38 -> 4940 | I38: =C38*D38 -> 3692 | J38: =H38-I38 -> 1248
A39: דוד בן חמו קבלן | B39: Ergash | C39: 51 | D39: 71 | E39: 95 | F39: קארו 3 | G39: 1180 | H39: =C39*E39 -> 4845 | I39: =C39*D39 -> 3621 | J39: =H39-I39 -> 1224
A40: נריה קידוח הצפון | B40: Kumar | C40: 87 | D40: 67 | E40: 80 | G40: 0 | H40: =C40*E40 -> 6960 | I40: =C40*D40 -> 5829 | J40: =H40-I40 -> 1131
A41: נריה קידוח הצפון | B41: Narendra | C41: 87 | D41: 67 | E41: 80 | G41: 0 | H41: =C41*E41 -> 6960 | I41: =C41*D41 -> 5829 | J41: =H41-I41 -> 1131
...

Sheet עובדים זרים - יוני
A1: עלות מכר ורווח גולמי - עובדים זרים - יוני
A3: סה"כ מכר (₪) | B3: =SUM(H9:H53) -> 707644.75
A4: סה"כ עלות מכר (₪) | B4: =SUM(I9:I53) -> 590480
A5: רווח גולמי (₪) | B5: =B3-B4 -> 117164.75
A6: שיעור רווח גולמי (%) | B6: =B5/B3 -> 0.16557001
D7: מקרא: | E7: 230 | F7: עובד שעבד פחות מ-230 שעות בחודש (חודש חלקי)
A8: מעסיק | B8: עובד | C8: שעות בפועל | D8: עלות מול תאגיד (₪/שעה) | E8: עלות גבייה שלנו (₪/שעה) | F8: דירת לינה | G8: ניכוי לינה (₪) | H8: הכנסה (₪) | I8: עלות מכר (₪) | J8: רווח גולמי (₪)
A9: אופיר קבלן | B9: akmal | C9: 242.5 | D9: 78 | E9: 90 | G9: 0 | H9: =C9*E9 -> 21825 | I9: =C9*D9 -> 18915 | J9: =H9-I9 -> 2910
A10: אופיר קבלן | B10: Farkhod | C10: 261.5 | D10: 78 | E10: 95 | G10: 0 | H10: =C10*E10 -> 24842.5 | I10: =C10*D10 -> 20397 | J10: =H10-I10 -> 4445.5
A11: אופיר קבלן | B11: Rustam | C11: 262.5 | D11: 78 | E11: 95 | G11: 0 | H11: =C11*E11 -> 24937.5 | I11: =C11*D11 -> 20475 | J11: =H11-I11 -> 4462.5
A12: אופיר קבלן | B12: samandar | C12: 187 | D12: 78 | E12: 90 | G12: 0 | H12: =C12*E12 -> 16830 | I12: =C12*D12 -> 14586 | J12: =H12-I12 -> 2244
A13: אחמד מצודת השלום | B13: harikesh | C13: 229 | D13: 64 | E13: 77 | F13: קארו 11 | G13: 1180 | H13: =C13*E13 -> 17633 | I13: =C13*D13 -> 14656 | J13: =H13-I13 -> 2977
A14: אחמד מצודת השלום | B14: kumar | C14: 239 | D14: 64 | E14: 77 | F14: קארו 11 | G14: 1180 | H14: =C14*E14 -> 18403 | I14: =C14*D14 -> 15296 | J14: =H14-I14 -> 3107
A15: אחמד מצודת השלום | B15: parimol | C15: 236 | D15: 64 | E15: 77 | F15: קארו 11 | G15: 1180 | H15: =C15*E15 -> 18172 | I15: =C15*D15 -> 15104 | J15: =H15-I15 -> 3068
A16: אחמד מצודת השלום | B16: ramishwar | C16: 228 | D16: 64 | E16: 77 | F16: קארו 11 | G16: 1180 | H16: =C16*E16 -> 17556 | I16: =C16*D16 -> 14592 | J16: =H16-I16 -> 2964
A17: אחמד מצודת השלום | B17: sanjay | C17: 220 | D17: 64 | E17: 77 | F17: קארו 11 | G17: 1180 | H17: =C17*E17 -> 16940 | I17: =C17*D17 -> 14080 | J17: =H17-I17 -> 2860
A18: אחמד מצודת השלום | B18: sri ram | C18: 238 | D18: 64 | E18: 77 | F18: קארו 11 | G18: 1180 | H18: =C18*E18 -> 18326 | I18: =C18*D18 -> 15232 | J18: =H18-I18 -> 3094
A19: אלי אביאלי | B19: Asatillo | C19: 29.5 | D19: 81 | E19: 92 | G19: 0 | H19: =C19*E19 -> 2714 | I19: =C19*D19 -> 2389.5 | J19: =H19-I19 -> 324.5
A20: אלי אביאלי | B20: sanjar | C20: 223 | D20: 81 | E20: 92 | G20: 0 | H20: =C20*E20 -> 20516 | I20: =C20*D20 -> 18063 | J20: =H20-I20 -> 2453
A21: אלי אביאלי | B21: Vasile | C21: 229 | D21: 83 | E21: 92 | G21: 0 | H21: =C21*E21 -> 21068 | I21: =C21*D21 -> 19007 | J21: =H21-I21 -> 2061
A22: אסף תאגיד השידור | B22: nagendra | C22: 201.375 | D22: 64 | E22: 75 | F22: קארו 7 | G22: 1180 | H22: =C22*E22 -> 15103.125 | I22: =C22*D22 -> 12888 | J22: =H22-I22 -> 2215.125
A23: אסף תאגיד השידור | B23: Praveen | C23: 201.375 | D23: 64 | E23: 75 | F23: קארו 7 | G23: 1180 | H23: =C23*E23 -> 15103.125 | I23: =C23*D23 -> 12888 | J23: =H23-I23 -> 2215.125
A24: גרייטדור | B24: dinoka | C24: 259.5 | D24: 70 | E24: 75 | G24: 0 | H24: =C24*E24 -> 19462.5 | I24: =C24*D24 -> 18165 | J24: =H24-I24 -> 1297.5
A25: גרייטדור | B25: Kamal | C25: 24 | D25: 70 | E25: 75 | G25: 0 | H25: =C25*E25 -> 1800 | I25: =C25*D25 -> 1680 | J25: =H25-I25 -> 120
A26: גרייטדור | B26: Liyana | C26: 24 | D26: 70 | E26: 75 | G26: 0 | H26: =C26*E26 -> 1800 | I26: =C26*D26 -> 1680 | J26: =H26-I26 -> 120
A27: גרייטדור | B27: ranjith | C27: 276.5 | D27: 70 | E27: 75 | G27: 0 | H27: =C27*E27 -> 20737.5 | I27: =C27*D27 -> 19355 | J27: =H27-I27 -> 1382.5
A28: גרייטדור | B28: Suresh | C28: 267 | D28: 70 | E28: 75 | G28: 0 | H28: =C28*E28 -> 20025 | I28: =C28*D28 -> 18690 | J28: =H28-I28 -> 1335
A29: גרייטדור | B29: susitha | C29: 267 | D29: 70 | E29: 75 | G29: 0 | H29: =C29*E29 -> 20025 | I29: =C29*D29 -> 18690 | J29: =H29-I29 -> 1335
A30: גרשון | B30: walikala | C30: 220 | D30: 65 | E30: 77 | G30: 0 | H30: =C30*E30 -> 16940 | I30: =C30*D30 -> 14300 | J30: =H30-I30 -> 2640
A31: דוד בן חמו קבלן | B31: akmal | C31: 10 | D31: 70 | E31: 95 | G31: 0 | H31: =C31*E31 -> 950 | I31: =C31*D31 -> 700 | J31: =H31-I31 -> 250
A32: דוד בן חמו קבלן | B32: bogir | C32: 53 | D32: 71 | E32: 95 | F32: קארו 3 | G32: 1180 | H32: =C32*E32 -> 5035 | I32: =C32*D32 -> 3763 | J32: =H32-I32 -> 1272
A33: דוד בן חמו קבלן | B33: Ergash | C33: 27 | D33: 71 | E33: 95 | F33: קארו 3 | G33: 1180 | H33: =C33*E33 -> 2565 | I33: =C33*D33 -> 1917 | J33: =H33-I33 -> 648
A34: נריה קידוח הצפון | B34: Kumar | C34: 38 | D34: 67 | E34: 80 | G34: 0 | H34: =C34*E34 -> 3040 | I34: =C34*D34 -> 2546 | J34: =H34-I34 -> 494
A35: נריה קידוח הצפון | B35: Narendra | C35: 38 | D35: 67 | E35: 80 | G35: 0 | H35: =C35*E35 -> 3040 | I35: =C35*D35 -> 2546 | J35: =H35-I35 -> 494
A36: רוטנברג | B36: biswas | C36: 237.5 | D36: 67 | E36: 77 | G36: 0 | H36: =C36*E36 -> 18287.5 | I36: =C36*D36 -> 15912.5 | J36: =H36-I36 -> 2375
A37: רוטנברג | B37: meena | C37: 237.5 | D37: 67 | E37: 77 | G37: 0 | H37: =C37*E37 -> 18287.5 | I37: =C37*D37 -> 15912.5 | J37: =H37-I37 -> 2375
A38: רמא | B38: azamat | C38: 267 | D38: 83 | E38: 105 | F38: קרית גת | G38: 1180 | H38: =C38*E38 -> 28035 | I38: =C38*D38 -> 22161 | J38: =H38-I38 -> 5874
A39: רמא | B39: daler | C39: 259 | D39: 75 | E39: 100 | G39: 0 | H39: =C39*E39 -> 25900 | I39: =C39*D39 -> 19425 | J39: =H39-I39 -> 6475
A40: רמא | B40: dmitri | C40: 255 | D40: 80 | E40: 100 | G40: 0 | H40: =C40*E40 -> 25500 | I40: =C40*D40 -> 20400 | J40: =H40-I40 -> 5100
A41: רמא | B41: erkin | C41: 231 | D41: 83 | E41: 100 | G41: 0 | H41: =C41*E41 -> 23100 | I41: =C41*D41 -> 19173 | J41: =H41-I41 -> 3927
...

Sheet דירות - ספטמבר
A1: עלות ורווח - דירות ושירותי קרקע - ספטמבר
A3: נכס | B3: לקוח | C3: יחידות | D3: תעריף ליחידה | E3: הכנסה (₪) | F3: שכירות (₪) | G3: שוטפות (₪) | H3: עמלת רועי (₪) | I3: סה"כ עלות (₪) | J3: רווח (₪) | K3: הערות
A4: קריית גת | B4: עובדים זרים (פנימי) | C4: 2 | D4: 1180 | E4: =C4*D4 -> 2360 | F4: 2500 | G4: 0 | H4: 0 | I4: =SUM(F4:H4) -> 2500 | J4: =E4-I4 -> -140 | K4: 2 עובדי רמא (shuhrok, azamat); לא משלמים חשמל. חודש אחרון - עזבנו את הדירה, השכירות האחרונה 2,500 שולמה 07/09
A5: בית חנינה (מלון) | B5: עובדים זרים (פנימי) | C5: 7 | D5: 1180 | E5: =C5*D5 -> 8260 | F5: 9600 | G5: 0 | H5: 0 | I5: =SUM(F5:H5) -> 9600 | J5: =E5-I5 -> -1340 | K5: 7 עובדים שלנו: 4 ברגשטיין (khasanjon, maruf, tukhtamurod, khurshed) + 3 אליעזר הקר (murod, odil, temurbek). שכירות 9,600 מכסה עד 12 - 5 מיטות פנויות. לא ידוע על הלנות של ד.י שרף בספטמבר
A6: קארו 3 | B6: עובדים זרים (פנימי) | C6: 4 | D6: 1180 | E6: =C6*D6 -> 4720 | F6: 4000 | G6: 800 | H6: 0 | I6: =SUM(F6:H6) -> 4800 | J6: =E6-I6 -> -80 | K6: 3 של ברגשטיין/הקר (damir, djamol, sanat - רשום "יוסף") + שי רם (narendra); 4 מתוך 5 מקומות; 200 ₪ לעובד
A7: קארו 7 - עובדים שלנו | B7: עובדים זרים (פנימי) | C7: 5 | D7: 1180 | E7: =C7*D7 -> 5900 | F7: =7000*5/8 -> 4375 | G7: 1000 | H7: 200 | I7: =SUM(F7:H7) -> 5575 | J7: =E7-I7 -> 325 | K7: אחמד 4 + אסף תאגיד השידור 1 (nagendra); שכירות לפי 5/8 מיטות מאוישות (15 מקומות, 7 ריקים); 200 ₪ לעובד; עמלת רועי 100 ₪ למיטה על parimol ו-kumar
A8: קארו 7 - מיטות איבריקה | B8: איבריקה | C8: 3 | D8: 1150 | E8: =C8*D8 -> 3450 | F8: =7000*3/8 -> 2625 | G8: 600 | H8: 300 | I8: =SUM(F8:H8) -> 3525 | J8: =E8-I8 -> -75 | K8: 3 מיטות איבריקה (כמו אוגוסט); שכירות לפי 3/8 מיטות מאוישות; 200 ₪ למיטה + עמלת רועי
A9: קארו 11 | B9: עובדים זרים (פנימי) | C9: 2 | D9: 1180 | E9: =C9*D9 -> 2360 | F9: 3000 | G9: 400 | H9: 0 | I9: =SUM(F9:H9) -> 3400 | J9: =E9-I9 -> -1040 | K9: ארי שבט בנימין 2 (sri ram, Praveen); 2 מתוך 4 מקומות - השכירות כולה עליהם; 200 ₪ לעובד. ש.ח.נ כרמלי כבר לא בקארו
A10: בית צפאפא | B10: אחים לימור | E10: 13000 | F10: 7500 | G10: 0 | H10: 0 | I10: =SUM(F10:H10) -> 7500 | J10: =E10-I10 -> 5500 | K10: ארנונה משולמת ע"י אחים לימור
A11: קורצאק | B11: אחים לימור | E11: 25000 | F11: 11000 | G11: 0 | H11: 0 | I11: =SUM(F11:H11) -> 11000 | J11: =E11-I11 -> 14000 | K11: ארנונה משולמת ע"י אחים לימור
A12: אשקלון | B12: איבריקה | C12: 1 | D12: 8816.66 | E12: =C12*D12 -> 8816.66 | F12: 4000 | G12: 0 | H12: 600 | I12: =SUM(F12:H12) -> 4600 | J12: =E12-I12 -> 4216.66 | K12: עמלת רועי 100x6; לא משלמים חשמל
A13: רבי חייא | B13: אלגרסי | E13: 20000 | F13: 15500 | G13: 0 | H13: 0 | I13: =SUM(F13:H13) -> 15500 | J13: =E13-I13 -> 4500 | K13: לא משלמים חשמל
A14: אסירי ציון | B14: איבריקה | C14: 1 | D14: 7283.33 | E14: =C14*D14 -> 7283.33 | F14: 4700 | G14: 1020 | H14: 600 | I14: =SUM(F14:H14) -> 6320 | J14: =E14-I14 -> 963.33 | K14: 6 עובדים x 170 ₪ + עמלת רועי
A15: סה"כ | E15: =SUM(E4:E14) -> 101149.99 | F15: =SUM(F4:F14) -> 68800 | G15: =SUM(G4:G14) -> 3820 | H15: =SUM(H4:H14) -> 1700 | I15: =SUM(I4:I14) -> 74320 | J15: =SUM(J4:J14) -> 26829.99
A17: הנחות שדורשות אישור: (1) "קארו" בקובץ השעות בלי מספר - הנחתי אחמד + nagendra בקארו 7 ו-ארי שבט בנימין בקארו 11, כמו באוגוסט. (2) ההשכרות החיצוניות (אחים לימור, אלגרסי, איבריקה) הועתקו מאוגוסט באותם סכומים. (3) עובדים שעזבו באמצע החודש (nagendra, sri ram, Praveen) חויבו לינה מלאה, כמו באוגוסט.

Sheet דירות - אוגוסט
A1: עלות ורווח - דירות ושירותי קרקע - אוגוסט
A3: נכס | B3: לקוח | C3: יחידות | D3: תעריף ליחידה | E3: הכנסה (₪) | F3: שכירות (₪) | G3: שוטפות (₪) | H3: עמלת רועי (₪) | I3: סה"כ עלות (₪) | J3: רווח (₪) | K3: הערות
A4: קריית גת | B4: עובדים זרים (פנימי) | C4: 3 | D4: 1180 | E4: =C4*D4 -> 3540 | F4: 2500 | G4: 0 | H4: 0 | I4: =SUM(F4:H4) -> 2500 | J4: =E4-I4 -> 1040 | K4: 3 עובדי רמא; לא משלמים חשמל
A5: בית חנינה (מלון) | B5: עובדים זרים (פנימי) + ד.י שרף | C5: 12 | D5: 1180 | E5: 14887.8 | F5: 9600 | G5: 0 | H5: 0 | I5: =SUM(F5:H5) -> 9600 | J5: =E5-I5 -> 5287.8 | K5: 9 עובדים שלנו (6 ברגשטיין + 3 אליעזר הקר) = 10,620 ₪, ועוד ד.י שרף השקעות = 4,267.80 ₪ (3 מיטות 5/8-28/8, 2 הלנות 6 ימים, מצעים). שכירות 9,600 מכסה עד 12 עובדים - הדירה מלאה
A6: קארו 3 | B6: עובדים זרים (פנימי) | C6: 4 | D6: 1180 | E6: =C6*D6 -> 4720 | F6: 4000 | G6: 800 | H6: 0 | I6: =SUM(F6:H6) -> 4800 | J6: =E6-I6 -> -80 | K6: 3 של ברגשטיין (רשום "יוסף") + שי רם; 4 מתוך 5 מקומות; 200 ₪ לעובד
A7: קארו 7 - עובדים שלנו | B7: עובדים זרים (פנימי) | C7: 6 | D7: 1180 | E7: =C7*D7 -> 7080 | F7: =7000*6/9 -> 4666.6667 | G7: 1200 | H7: 200 | I7: =SUM(F7:H7) -> 6066.6667 | J7: =E7-I7 -> 1013.3333 | K7: אחמד 4 + אסף תאגיד השידור 2; שכירות לפי 6/9 מיטות מאוישות (15 מקומות, 6 ריקים); 200 ₪ לעובד; עמלת רועי 100 ₪ למיטה על parimol ו-kumar
A8: קארו 7 - מיטות איבריקה | B8: איבריקה | C8: 3 | D8: 1150 | E8: =C8*D8 -> 3450 | F8: =7000*3/9 -> 2333.3333 | G8: 600 | H8: 300 | I8: =SUM(F8:H8) -> 3233.3333 | J8: =E8-I8 -> 216.66667 | K8: 3 מיטות איבריקה; שכירות לפי 3/9 מיטות מאוישות; 200 ₪ למיטה + עמלת רועי
A9: קארו 11 | B9: עובדים זרים (פנימי) | C9: 4 | D9: 1180 | E9: =C9*D9 -> 4720 | F9: 3000 | G9: 800 | H9: 0 | I9: =SUM(F9:H9) -> 3800 | J9: =E9-I9 -> 920 | K9: ארי שבט בנימין 2 + ש.ח.נ כרמלי 2; 4 מתוך 4 מקומות; 200 ₪ לעובד
A10: בית צפאפא | B10: אחים לימור | E10: 13000 | F10: 7500 | G10: 0 | H10: 0 | I10: =SUM(F10:H10) -> 7500 | J10: =E10-I10 -> 5500 | K10: ארנונה משולמת ע"י אחים לימור
A11: קורצאק | B11: אחים לימור | E11: 25000 | F11: 11000 | G11: 0 | H11: 0 | I11: =SUM(F11:H11) -> 11000 | J11: =E11-I11 -> 14000 | K11: ארנונה משולמת ע"י אחים לימור
A12: אשקלון | B12: איבריקה | C12: 1 | D12: 8816.66 | E12: =C12*D12 -> 8816.66 | F12: 4000 | G12: 0 | H12: 600 | I12: =SUM(F12:H12) -> 4600 | J12: =E12-I12 -> 4216.66 | K12: עמלת רועי 100x6; לא משלמים חשמל
A13: רבי חייא | B13: אלגרסי | E13: 20000 | F13: 15500 | G13: 0 | H13: 0 | I13: =SUM(F13:H13) -> 15500 | J13: =E13-I13 -> 4500 | K13: לא משלמים חשמל
A14: אסירי ציון | B14: איבריקה | C14: 1 | D14: 7283.33 | E14: =C14*D14 -> 7283.33 | F14: 4700 | G14: 1020 | H14: 600 | I14: =SUM(F14:H14) -> 6320 | J14: =E14-I14 -> 963.33 | K14: 6 עובדים x 170 ₪ + עמלת רועי
A15: סה"כ | E15: =SUM(E4:E14) -> 112497.79 | F15: =SUM(F4:F14) -> 68800 | G15: =SUM(G4:G14) -> 4420 | H15: =SUM(H4:H14) -> 1700 | I15: =SUM(I4:I14) -> 74920 | J15: =SUM(J4:J14) -> 37577.79
A17: הנחות שדורשות אישור: (1) חלוקת 10 המיטות ב"קארו" - הנחתי 6 בקארו 7 (אחמד + אסף) ו-4 בקארו 11 (ארי שבט בנימין + כרמלי), כי בקובץ השעות רשום "קארו" בלי מספר. (2) ההשכרות החיצוניות (אחים לימור, אלגרסי, איבריקה) הועתקו מיולי באותם סכומים.

Sheet דירות - שירותי קרקע
A1: עלות ורווח - דירות ושירותי קרקע - יולי
A3: נכס | B3: לקוח | C3: יחידות | D3: תעריף ליחידה | E3: הכנסה (₪) | F3: שכירות (₪) | G3: שוטפות (₪) | H3: עמלת רועי (₪) | I3: סה"כ עלות (₪) | J3: רווח (₪) | K3: הערות
A4: קריית גת | B4: עובדים זרים (פנימי) | C4: 3 | D4: 1180 | E4: =C4*D4 -> 3540 | F4: 2500 | G4: 0 | H4: 0 | I4: =SUM(F4:H4) -> 2500 | J4: =E4-I4 -> 1040 | K4: 3 עובדי רמא; לא משלמים חשמל
A5: בית חנינה (מלון) | B5: עובדים זרים (פנימי) | C5: 10 | D5: 1180 | E5: =C5*D5 -> 11800 | F5: =9600+MAX(0,C5-12)*800 -> 9600 | G5: 0 | H5: 0 | I5: =SUM(F5:H5) -> 9600 | J5: =E5-I5 -> 2200 | K5: שכירות 9,600 ₪ עד 12 עובדים, +800 ₪ לכל עובד נוסף; לא משלמים חשמל
A6: קארו 3 | B6: עובדים זרים (פנימי) | C6: 6 | D6: 1180 | E6: =C6*D6 -> 7080 | F6: 4000 | G6: 1200 | H6: 0 | I6: =SUM(F6:H6) -> 5200 | J6: =E6-I6 -> 1880 | K6: 6 עובדים x 200 ₪
A7: קארו 7 - עובדים שלנו | B7: עובדים זרים (פנימי) | C7: 10 | D7: 1180 | E7: =C7*D7 -> 11800 | F7: =7000*10/13 -> 5384.6154 | G7: 2000 | H7: 200 | I7: =SUM(F7:H7) -> 7584.6154 | J7: =E7-I7 -> 4215.3846 | K7: 10 עובדים x 200 ₪; שכירות לפי 10/13 מיטות; עמלת רועי 100 ₪ למיטה על parimol ו-kumar
A8: קארו 7 - מיטות איבריקה | B8: איבריקה | C8: 3 | D8: 1150 | E8: =C8*D8 -> 3450 | F8: =7000*3/13 -> 1615.3846 | G8: 600 | H8: 300 | I8: =SUM(F8:H8) -> 2515.3846 | J8: =E8-I8 -> 934.61538 | K8: 3 מיטות איבריקה x 200 ₪ + עמלת רועי; שכירות לפי 3/13 מיטות
A9: קארו 11 | B9: עובדים זרים (פנימי) | C9: 4 | D9: 1180 | E9: =C9*D9 -> 4720 | F9: 3000 | G9: 800 | H9: 0 | I9: =SUM(F9:H9) -> 3800 | J9: =E9-I9 -> 920 | K9: 4 עובדים x 200 ₪
A10: בית צפאפא | B10: אחים לימור | E10: 13000 | F10: 7500 | G10: 0 | H10: 0 | I10: =SUM(F10:H10) -> 7500 | J10: =E10-I10 -> 5500 | K10: ארנונה משולמת ע"י אחים לימור
A11: קורצאק | B11: אחים לימור | E11: 25000 | F11: 11000 | G11: 0 | H11: 0 | I11: =SUM(F11:H11) -> 11000 | J11: =E11-I11 -> 14000 | K11: ארנונה משולמת ע"י אחים לימור
A12: אשקלון | B12: איבריקה | C12: 1 | D12: 8816.66 | E12: =C12*D12 -> 8816.66 | F12: 4000 | G12: 0 | H12: 600 | I12: =SUM(F12:H12) -> 4600 | J12: =E12-I12 -> 4216.66 | K12: עמלת רועי 100x6; לא משלמים חשמל
A13: רבי חייא | B13: אלגרסי | E13: 20000 | F13: 15500 | G13: 0 | H13: 0 | I13: =SUM(F13:H13) -> 15500 | J13: =E13-I13 -> 4500 | K13: לא משלמים חשמל
A14: אסירי ציון | B14: איבריקה | C14: 1 | D14: 7283.33 | E14: =C14*D14 -> 7283.33 | F14: 4700 | G14: 1020 | H14: 600 | I14: =SUM(F14:H14) -> 6320 | J14: =E14-I14 -> 963.33 | K14: 6 עובדים x 170 ₪ + עמלת רועי
A15: סה"כ | E15: =SUM(E4:E14) -> 116489.99 | F15: =SUM(F4:F14) -> 68800 | G15: =SUM(G4:G14) -> 5620 | H15: =SUM(H4:H14) -> 1700 | I15: =SUM(I4:I14) -> 76120 | J15: =SUM(J4:J14) -> 40369.99

Sheet דירות - יוני
A1: עלות ורווח - דירות ושירותי קרקע - יוני
A3: נכס | B3: לקוח | C3: יחידות | D3: תעריף ליחידה | E3: הכנסה (₪) | F3: שכירות (₪) | G3: שוטפות (₪) | H3: עמלת רועי (₪) | I3: סה"כ עלות (₪) | J3: רווח (₪) | K3: הערות
A4: קארו 11 | B4: עובדים זרים (פנימי) | C4: 4 | D4: 1180 | E4: 4720 | F4: 3000 | G4: 800 | H4: 0 | I4: =SUM(F4:H4) -> 3800 | J4: =E4-I4 -> 920 | K4: 4 עובדים x 200 ₪ (מצודת השלום)
A5: קארו 3 | B5: עובדים זרים (פנימי) | C5: 5 | D5: 1180 | E5: 5900 | F5: 4000 | G5: 1000 | H5: 0 | I5: =SUM(F5:H5) -> 5000 | J5: =E5-I5 -> 900 | K5: 5 עובדים x 200 ₪ (ברגשטיין + דוד קבלן)
A6: קארו 7 - עובדים שלנו | B6: עובדים זרים (פנימי) | C6: 4 | D6: 1180 | E6: 4720 | F6: =7000*4/6 -> 4666.6667 | G6: 800 | H6: 0 | I6: =SUM(F6:H6) -> 5466.6667 | J6: =E6-I6 -> -746.66667 | K6: שבט בנימין 2 + מצודת השלום 2; 200 ₪ לעובד; שכירות לפי 4/6 מיטות
A7: קארו 7 - מיטות איבריקה | B7: איבריקה | C7: 2 | D7: 1100 | E7: 2200 | F7: =7000*2/6 -> 2333.3333 | G7: 400 | H7: 0 | I7: =SUM(F7:H7) -> 2733.3333 | J7: =E7-I7 -> -533.33333 | K7: 2 מיטות איבריקה; 200 ₪ למיטה; שכירות לפי 2/6 מיטות
A8: אשקלון (בן גוריון) | B8: איבריקה | E8: 8625 | F8: 4000 | G8: 0 | H8: 900 | I8: =SUM(F8:H8) -> 4900 | J8: =E8-I8 -> 3725
A9: אסירי ציון | B9: איבריקה | C9: 10 | E9: 11500 | F9: 4700 | G9: 1700 | H9: 1000 | I9: =SUM(F9:H9) -> 7400 | J9: =E9-I9 -> 4100 | K9: 10 עובדים x 170 ₪ + עמלת רועי
A10: בית צפאפא | B10: אחים לימור | E10: 13000 | F10: 7500 | G10: 0 | H10: 0 | I10: =SUM(F10:H10) -> 7500 | J10: =E10-I10 -> 5500 | K10: השכרה לגורם חיצוני - לא לפי מיטות
A11: קורצאק | B11: אחים לימור | E11: 25000 | F11: 11000 | G11: 0 | H11: 0 | I11: =SUM(F11:H11) -> 11000 | J11: =E11-I11 -> 14000 | K11: השכרה לגורם חיצוני - לא לפי מיטות
A12: ברוריה (רבי חייא) | B12: אלגרסי | E12: 20000 | F12: 15500 | G12: 0 | H12: 0 | I12: =SUM(F12:H12) -> 15500 | J12: =E12-I12 -> 4500 | K12: השכרה לגורם חיצוני - לא לפי מיטות
A13: קריית גת | B13: עובדים זרים (פנימי) | C13: 2 | D13: 1250 | E13: 2500 | F13: 2500 | G13: 0 | H13: 0 | I13: =SUM(F13:H13) -> 2500 | J13: =E13-I13 -> 0 | K13: רמא - SHUHROK, azamat
A14: סה"כ | E14: =SUM(E4:E13) -> 98165 | F14: =SUM(F4:F13) -> 59200 | G14: =SUM(G4:G13) -> 4700 | H14: =SUM(H4:H13) -> 1900 | I14: =SUM(I4:I13) -> 65800 | J14: =SUM(J4:J13) -> 32365
A16: מקור: דוח_רווח_והפסד_יוני_2026 (20).xlsx, גיליון "דירות". דמי השכירות זהים לחודש יולי בכל הנכסים; ההפרש בסה"כ (59,200 מול 67,200) נובע מכך שבית חנינה (8,000 ₪) נוסף רק ביולי.

Sheet סיכום מאוחד
A1: סיכום מאוחד - ישר שירותי קרקע - יולי
A3: עובדים זרים - מכר | B3: ='עובדים זרים - יולי'!B3 -> 971024.5
A4: עובדים זרים - עלות מכר | B4: ='עובדים זרים - יולי'!B4 -> 795551.25
A5: עובדים זרים - רווח גולמי | B5: ='עובדים זרים - יולי'!B5 -> 175473.25
A8: דירות - הכנסה כוללת | B8: ='דירות - שירותי קרקע'!E15 -> 116489.99
A9: דירות - עלות כוללת | B9: ='דירות - שירותי קרקע'!I15 -> 76120
A10: דירות - רווח | B10: =B8-B9 -> 40369.99
A11: מתוכו: רווח מלינת עובדים | B11: =('דירות - שירותי קרקע'!E4+'דירות - שירותי קרקע'!E5+'דירות - שירותי קרקע'!E6+'דירות - שירותי קרקע'!E7+'דירות - שירותי קרקע'!E9)-('דירות - שירותי קרקע'!I4+'דירות - שירותי קרקע'!I5+'דירות - שירותי קרקע'!I6+'דירות - שירותי קרקע'!I7+'דירות - שירותי קרקע'!I9) -> 10255.385
A12: מתוכו: רווח מהשכרה חיצונית | B12: =B10-B11 -> 30114.605
A14: רווח גולמי מאוחד | B14: =B5+B10 -> 215843.24
A15: עמלת שלמה מינסקי | B15: =E37 -> 7400
A16: עמלת רועי (2 ₪ לשעה - parimol, kumar) | B16: =C94 -> 926
A17: הוצאות תפעוליות (חלק ישר שירותי קרקע) | B17: ='הוצאות תפעוליות'!D15 -> 68946.565
A19: רווח נקי סופי - ישר שירותי קרקע - יולי | B19: =B14-B15-B16-B17 -> 138570.67
A21: פירוט לפי לקוח - יולי
A22: לקוח | B22: עובדים | C22: מכר (₪) | D22: עלות מכר (₪) | E22: עמלת שלמה (₪) | F22: רווח גולמי (₪) | G22: שיעור
A23: שלום ברגשטיין | B23: 18 | C23: 239146 | D23: 182207.25 | E23: 1800 | F23: =C23-D23-E23 -> 55138.75 | G23: =F23/C23 -> 0.23056522
A24: רמא | B24: 6 | C24: 155360 | D24: 122360 | E24: 0 | F24: =C24-D24-E24 -> 33000 | G24: =F24/C24 -> 0.21240989
A25: גרייטדור | B25: 8 | C25: 135000 | D25: 126310.5 | E25: 0 | F25: =C25-D25-E25 -> 8689.5 | G25: =F25/C25 -> 0.064366667
A26: אחמד מצודת השלום | B26: 8 | C26: 94017 | D26: 71553.5 | E26: 800 | F26: =C26-D26-E26 -> 21663.5 | G26: =F26/C26 -> 0.23042109
A27: אופיר קבלן | B27: 4 | C27: 88602.5 | D27: 74646 | E27: 2400 | F27: =C27-D27-E27 -> 11556.5 | G27: =F27/C27 -> 0.13043086
A28: ש.ח.נ כרמלי | B28: 5 | C28: 87238 | D28: 73711 | E28: 800 | F28: =C28-D28-E28 -> 12727 | G28: =F28/C28 -> 0.14588826
A29: אלי אביאלי | B29: 3 | C29: 42872 | D29: 38164 | E29: 0 | F29: =C29-D29-E29 -> 4708 | G29: =F29/C29 -> 0.10981526
A30: רוטנברג | B30: 2 | C30: 34419 | D30: 29949 | E30: 800 | F30: =C30-D30-E30 -> 3670 | G30: =F30/C30 -> 0.10662715
A31: אסף תאגיד השידור | B31: 2 | C31: 30750 | D31: 26445 | E31: 800 | F31: =C31-D31-E31 -> 3505 | G31: =F31/C31 -> 0.11398374
A32: דוד בן חמו קבלן | B32: 3 | C32: 18050 | D32: 13403 | E32: 0 | F32: =C32-D32-E32 -> 4647 | G32: =F32/C32 -> 0.25745152
A33: גרשון | B33: 1 | C33: 16170 | D33: 13650 | E33: 0 | F33: =C33-D33-E33 -> 2520 | G33: =F33/C33 -> 0.15584416
A34: נריה קידוח הצפון | B34: 2 | C34: 13920 | D34: 11658 | E34: 0 | F34: =C34-D34-E34 -> 2262 | G34: =F34/C34 -> 0.1625
... A36: שי רם חברה לבנייה | B36: 2 | C36: 6930 | D36: 5805 | E36: 0 | F36: =C36-D36-E36 -> 1125 | G36: =F36/C36 -> 0.16233766
A37: סה"כ | B37: =SUM(B23:B36) -> 66 | C37: =SUM(C23:C36) -> 971024.5 | D37: =SUM(D23:D36) -> 796477.25 | E37: =SUM(E23:E36) -> 7400 | F37: =SUM(F23:F36) -> 167147.25 | G37: =F37/C37 -> 0.17213495
A39: עמלת שלמה מינסקי: 2 ₪ לשעה על עובד הודי ו-3 ₪ לשעה על עובד אוזבקי, לפי 200 שעות לעובד. הפירוט לפי עובד נמצא בעמודה K בגיליון "עובדים זרים - יולי".
A41: פירוט לפי לקוח - יוני
A42: לקוח | B42: עובדים | C42: מכר (₪) | D42: עלות מכר (₪) | E42: עמלת שלמה (₪) | F42: רווח גולמי (₪) | G42: שיעור
A43: שלום ברגשטיין | B43: 5 | C43: 95068 | D43: 81491 | E43: 1800 | F43: =C43-D43-E43 -> 11777 | G43: =F43/C43 -> 0.12387975
A44: רמא | B44: 6 | C44: 154955 | D44: 120583 | E44: 0 | F44: =C44-D44-E44 -> 34372 | G44: =F44/C44 -> 0.22181924
A45: גרייטדור | B45: 6 | C45: 83850 | D45: 78260 | E45: 0 | F45: =C45-D45-E45 -> 5590 | G45: =F45/C45 -> 0.066666667
A46: אחמד מצודת השלום | B46: 6 | C46: 107030 | D46: 88960 | E46: 2400 | F46: =C46-D46-E46 -> 15670 | G46: =F46/C46 -> 0.14640755
A47: אופיר קבלן | B47: 4 | C47: 88435 | D47: 74373 | E47: 2400 | F47: =C47-D47-E47 -> 11662 | G47: =F47/C47 -> 0.13187087
A48: ש.ח.נ כרמלי | B48: 4 | C48: 35657.5 | D48: 23980.5 | E48: 0 | F48: =C48-D48-E48 -> 11677 | G48: =F48/C48 -> 0.32747669
A49: אלי אביאלי | B49: 3 | C49: 44298 | D49: 39459.5 | E49: 0 | F49: =C49-D49-E49 -> 4838.5 | G49: =F49/C49 -> 0.10922615
...

Sheet הוצאות תפעוליות
A1: הוצאות תפעוליות יולי
A2: משותפות לשתי החברות (מטה ופתילים + ישר שירותי קרקע)
A4: סעיף | B4: סכום מלא (₪) | C4: % לישר שירותי קרקע | D4: חלק ישר שירותי קרקע (₪)
A5: משרד (שכירות+ניהול+מיזוג+ארנונה) * | B5: 9547.13 | C5: 0.5 | D5: =B5*C5 -> 4773.565
A6: רואה חשבון | B6: 1357 | C6: 1 | D6: =B6*C6 -> 1357
A7: עורך דין | B7: 3540 | C7: 0.5 | D7: =B7*C7 -> 1770
A8: שכר נחשון (ברוטו) | B8: 6811 | C8: 1 | D8: =B8*C8 -> 6811
A9: שכר עדינה (ברוטו) | B9: 11850 | C9: 1 | D9: =B9*C9 -> 11850
A10: שכר שלמה מינסקי (ברוטו) ** | B10: 19193 | C10: 1 | D10: =B10*C10 -> 19193
A11: שכר רז עדן חנה (ברוטו) - תלוש דרך שלמה מינסקי | B11: 11533 | C11: 1 | D11: =B11*C11 -> 11533
A12: ש. מינסקי יזמות - חשבונית * | B12: 14000 | C12: 0.5 | D12: =B12*C12 -> 7000
A13: ג.ד קלאמרה - ג'מלים לבנייה (חשבונית 20005) | B13: 2832 | C13: 1 | D13: =B13*C13 -> 2832
A14: ביטוח רכב סיטרואן (עובדי כרמלי) | B14: 1827 | C14: 1 | D14: =B14*C14 -> 1827 | E14: תקופת הביטוח 06/07/2026 - 30/06/2027
A15: סה"כ | D15: =SUM(D5:D14) -> 68946.565
A17: * ללא מע"מ. חשבונית ש. מינסקי יזמות: 14,000 + מע"מ = 16,520 ₪, כפי ששולם בתזרים ב-13/07/2026.
A18: ** כולל תשלום מילואים שאמור לחזור מביטוח לאומי - כשיתקבל סכום ההחזר יש לקזז אותו כאן
A21: רכב סיטרואן - עובדי ש.ח.נ כרמלי
A22: ביטוח הרכב 1,827 ₪ (06/07/2026-30/06/2027) נרשם במלואו ביולי כהוצאה תפעולית כללית, 100% ישר.
A23: עלות הרכב עצמו (ליסינג/רכישה) - טרם התקבלה.
A25: רכב סיטרואן - פירוט תשלומים
A26: 03/06/2026 - 21,375 ₪ | 07/06/2026 - 2,357 ₪ | סה"כ 23,732 ₪ - נזקף לחודש יוני
A27: ביטוח 1,827 ₪ (06/07/2026-30/06/2027) - נזקף לחודש יולי
A30: הוצאות תפעוליות אוגוסט
A31: משותפות לשתי החברות (מטה ופתילים + ישר שירותי קרקע)
A33: סעיף | B33: סכום מלא (₪) | C33: % לישר שירותי קרקע | D33: חלק ישר שירותי קרקע (₪)
A34: משרד (שכירות+ניהול+מיזוג+ארנונה) * | C34: 0.5 | D34: =B34*C34 -> 0
A35: רואה חשבון | C35: 1 | D35: =B35*C35 -> 0
A36: עורך דין | C36: 0.5 | D36: =B36*C36 -> 0
A37: שכר נחשון (ברוטו) | B37: 17017 | C37: 1 | D37: =B37*C37 -> 17017 | E37: תלוש 8/26. ביולי 6,811
A38: שכר עדינה (ברוטו) | B38: 14323 | C38: 1 | D38: =B38*C38 -> 14323 | E38: תלוש 8/26: 133.41 שעות x 105 ₪ = 14,008 + נסיעות 315. ביולי 11,850
A39: שכר שלמה מינסקי (ברוטו) ** | C39: 1 | D39: =B39*C39 -> 0
A40: שכר רז עדן חנה (ברוטו) - תלוש דרך שלמה מינסקי | C40: 1 | D40: =B40*C40 -> 0
A41: ש. מינסקי יזמות - חשבונית * | C41: 0.5 | D41: =B41*C41 -> 0
A42: ג.ד קלאמרה - ייעוץ הנדסי ופיקוח (חשבונית 20019) | B42: 3461.86 | C42: 1 | D42: =B42*C42 -> 3461.86 | E42: ללא מע"מ (4,085 כולל מע"מ). חודש ביצוע 08/26
A43: ביטוח רכב סיטרואן (עובדי כרמלי) | B43: 0 | C43: 1 | D43: =B43*C43 -> 0 | E43: נזקף במלואו ביולי
A44: סה"כ (חלקי - חסרים 6 סעיפים) | D44: =SUM(D34:D43) -> 34801.86
A46: * ללא מע"מ. אוגוסט כרגע כולל רק שכר נחשון, שכר עדינה וקלמרה - יתר הסעיפים יתווספו כשיתקבלו.
A49: הוצאות תפעוליות ספטמבר
A50: משותפות לשתי החברות (מטה ופתילים + ישר שירותי קרקע)
A52: סעיף | B52: סכום מלא (₪) | C52: % לישר שירותי קרקע | D52: חלק ישר שירותי קרקע (₪)
...

Sheet מעקב תשלומים
A1: חובות פתוחים - ישר שירותי קרקע
A2: מציג רק לקוחות עם יתרה פתוחה. מי ששילם במלואו הוסר. מסונכרן מול התזרים עד 07.09.2026.
A4: לקוח | B4: חיוב כולל מע"מ (₪) | C4: שולם (₪) | D4: יתרה לגבייה (₪) | E4: הערות
A5: גרייטדור | B5: 159300 | C5: 52488 | D5: =B5-C5 -> 106812 | E5: צ'ק 110,000 בניכיון - 50,000 התקבלו, יתרה 60,000 בחודש הבא
A6: דוד בן חמו קבלן | B6: 21299 | C6: 4000 | D6: =B6-C6 -> 17299 | E6: שולם 4,000 ₪ במזומן (לא דרך הבנק). הסכם: 4,000 ₪ כל יום רביעי דרך נחשון
A7: חוב מיוני: מע"מ NH Clinics / דוד בן חמו | B7: 1504.8 | C7: 0 | D7: =B7-C7 -> 1504.8
A8: ברגשטיין מקבוצת בי אנד גי | B8: 286847 | C8: 0 | D8: =B8-C8 -> 286847
A9: גרייטדור - חשבון עסקה אוגוסט | B9: 248597 | C9: 0 | D9: =B9-C9 -> 248597
A10: רמא - ר.מ. טכנולוגיות | B10: 129446 | C10: 0 | D10: =B10-C10 -> 129446
A11: אופיר חנון בניה ופיקוח | B11: 113425 | C11: 0 | D11: =B11-C11 -> 113425
A12: ש.ח.ן כרמלי עבודות קבלנויות | B12: 98230 | C12: 0 | D12: =B12-C12 -> 98230
A13: מצודת השלום | B13: 91496 | C13: 0 | D13: =B13-C13 -> 91496
A14: שבט בנימין | B14: 48156.3 | C14: 0 | D14: =B14-C14 -> 48156.3
A15: אביאלי אלומיניום | B15: 42772.64 | C15: 0 | D15: =B15-C15 -> 42772.64
A16: איבריקה אינטרנשיונל | B16: 23069 | C16: 0 | D16: =B16-C16 -> 23069
A17: שי- רם חברה לבניה | B17: 18990 | C17: 0 | D17: =B17-C17 -> 18990
A18: מאי חברה למערכות חשמל | B18: 12675 | C18: 0 | D18: =B18-C18 -> 12675
A19: סה"כ לגבייה | B19: =SUM(B5:B18) -> 1295807.7 | C19: =SUM(C5:C18) -> 56488 | D19: =SUM(D5:D18) -> 1239319.7

Sheet השוואה חודשית
A1: השוואה חודשית 2026 - ישר שירותי קרקע לקבלן ולפועל בע"מ
A2: נטו ללא מע"מ. כל החודשים מחושבים באותה שיטה - לפי שעות עבודה בפועל. עמודות השינוי מציגות אוגוסט מול ספטמבר.
A4: עובדים זרים | B4: יוני 2026 | C4: יולי 2026 | D4: אוגוסט 2026 | E4: ספטמבר 2026 | F4: שינוי (₪) | G4: שינוי (%)
A5: הכנסה | B5: ='עובדים זרים - יוני'!B3 -> 707644.75 | C5: ='עובדים זרים - יולי'!B3 -> 971024.5 | D5: ='עובדים זרים - אוגוסט'!B3 -> 1047144.5 | E5: ='עובדים זרים - ספטמבר'!B3 -> 682461.5 | F5: =E5-D5 -> -364683 | G5: =E5/D5-1 -> -0.34826426
A6: עלות מכר לתאגידים | B6: ='עובדים זרים - יוני'!B4 -> 590480 | C6: ='עובדים זרים - יולי'!B4 -> 795551.25 | D6: ='עובדים זרים - אוגוסט'!B4 -> 881166 | E6: ='עובדים זרים - ספטמבר'!B4 -> 569835.5 | F6: =E6-D6 -> -311330.5 | G6: =E6/D6-1 -> -0.35331651
A7: חיוב לינה (נכלל ברווח הדירות) | B7: =SUM('עובדים זרים - יוני'!G9:G53) -> 17700 | C7: ='עובדים זרים - יולי'!G75 -> 38940 | D7: ='עובדים זרים - אוגוסט'!G68 -> 30680 | E7: ='עובדים זרים - ספטמבר'!G59 -> 23600 | F7: =E7-D7 -> -7080 | G7: =E7/D7-1 -> -0.23076923
A8: רווח גולמי | B8: ='עובדים זרים - יוני'!B5 -> 117164.75 | C8: ='עובדים זרים - יולי'!B5 -> 175473.25 | D8: ='עובדים זרים - אוגוסט'!B5 -> 165978.5 | E8: ='עובדים זרים - ספטמבר'!B5 -> 112626 | F8: =E8-D8 -> -53352.5 | G8: =E8/D8-1 -> -0.32144223
A9: שיעור רווח גולמי | B9: =B8/B5 -> 0.16557001 | C9: =C8/C5 -> 0.1807094 | D9: =D8/D5 -> 0.15850582 | E9: =E8/E5 -> 0.16502909 | F9: =E9-D9 -> 0.0065232673
A11: הכנסה לפי לקוח | B11: יוני 2026 | C11: יולי 2026 | D11: אוגוסט 2026 | E11: ספטמבר 2026 | F11: שינוי (₪) | G11: סיבת השינוי
A12: שלום ברגשטיין | B12: 95068 | C12: 239146 | D12: 243091 | E12: =SUMIF('עובדים זרים - ספטמבר'!$A$9:$A$58,"שלום ברגשטיין",'עובדים זרים - ספטמבר'!$H$9:$H$58) -> 132545 | F12: =E12-D12 -> -110546 | G12: ירידה של 110,546 ₪ (-45%). מ-11 עובדים ל-9: shakhzod ו-orzu כבר לא אצלו, ו-sanat עבר ב-3 לחודש לאליעזר הקר (34.5 שעות בלבד כאן). העיקר הוא השעות: 1,415 מול 2,568 - ממוצע 157 שעות לעובד מול 233 באוגוסט. התעריף הממוצע כמעט זהה (93.7 ₪ מול 94.7).
A13: רמא | B13: 154955 | C13: 155360 | D13: 109700 | E13: =SUMIF('עובדים זרים - ספטמבר'!$A$9:$A$58,"רמא",'עובדים זרים - ספטמבר'!$H$9:$H$58) -> 94950 | F13: =E13-D13 -> -14750 | G13: ירידה של 14,750 ₪ (-13%). אותם 6 עובדים, אבל השעות ירדו מ-1,081 ל-934: dmitri עבד 31 שעות בלבד (221 באוגוסט). מנגד daler חזר לחודש כמעט מלא (199 שעות מול 32). התעריף הממוצע זהה (101.7 ₪).
A14: ש.ח.נ כרמלי | B14: 35657.5 | C14: 87238 | D14: 83245.5 | E14: =SUMIF('עובדים זרים - ספטמבר'!$A$9:$A$58,"ש.ח.נ כרמלי",'עובדים זרים - ספטמבר'!$H$9:$H$58) -> 65490 | F14: =E14-D14 -> -17755.5 | G14: ירידה של 17,756 ₪ (-21%). מ-6 עובדים ל-4: sri ram, ramishwar ו-Kamoliddin כבר לא אצלו, ונוסף amirbek (98 שעות). השעות ירדו מ-981.5 ל-789. בנוסף ירד תעריף הגבייה: andrei מ-90 ל-87 ₪, alexandr ו-abdurauf מ-85 ל-83 ול-80 ₪.
A15: גרייטדור | B15: 83850 | C15: 135000 | D15: 244762.5 | E15: =SUMIF('עובדים זרים - ספטמבר'!$A$9:$A$58,"גרייטדור",'עובדים זרים - ספטמבר'!$H$9:$H$58) -> 135600 | F15: =E15-D15 -> -109162.5 | G15: ירידה של 109,163 ₪ (-45%). מ-14 עובדים ל-12: thusitha ו-Chamila כבר לא אצלו, ו-rishan ו-Nilanth (פסגת ליאם) בוטלו באמצע החודש (68 ו-85 שעות). השעות ירדו מ-3,263.5 ל-1,808 - ממוצע 151 שעות לעובד מול 233. התעריף קבוע 75 ₪.
A16: מצודת השלום (אחמד) | B16: 107030 | C16: 94017 | D16: 77539 | E16: =SUMIF('עובדים זרים - ספטמבר'!$A$9:$A$58,"אחמד מצודת השלום",'עובדים זרים - ספטמבר'!$H$9:$H$58) -> 47316.5 | F16: =E16-D16 -> -30222.5 | G16: ירידה של 30,223 ₪ (-39%). אותם 4 עובדים, אבל השעות ירדו מ-1,007 ל-614.5 - ממוצע 154 שעות לעובד מול 252. התעריף קבוע 77 ₪.
A17: אופיר חנון / אופיר קבלן | B17: 88435 | C17: 88602.5 | D17: 94052.5 | E17: =SUMIF('עובדים זרים - ספטמבר'!$A$9:$A$58,"אופיר קבלן",'עובדים זרים - ספטמבר'!$H$9:$H$58) -> 56417.5 | F17: =E17-D17 -> -37635 | G17: ירידה של 37,635 ₪ (-40%). אותם 4 עובדים, אבל השעות ירדו מ-1,016 ל-609 - ממוצע 152 שעות לעובד מול 254. התעריפים זהים (90/95 ₪), וכולם עם עמלה של 2 ₪ לשעה לעובד.
A18: אביאלי / אלי אביאלי | B18: 44298 | C18: 42872 | D18: 36248 | E18: =SUMIF('עובדים זרים - ספטמבר'!$A$9:$A$58,"אלי אביאלי",'עובדים זרים - ספטמבר'!$H$9:$H$58) -> 13340 | F18: =E18-D18 -> -22908 | G18: ירידה של 22,908 ₪ (-63%). מ-2 עובדים ל-1: sanjar כבר לא אצלו. Vasile עבד 145 שעות מול 216 באוגוסט. התעריף קבוע 92 ₪.
A19: מ. רוטנברג | B19: 36575 | C19: 34419 | D19: 34804 | E19: =SUMIF('עובדים זרים - ספטמבר'!$A$9:$A$58,"רוטנברג",'עובדים זרים - ספטמבר'!$H$9:$H$58) -> 29337 | F19: =E19-D19 -> -5467 | G19: ירידה של 5,467 ₪ (-16%). אותם 2 עובדים, אבל 381 שעות מול 452. התעריף קבוע 77 ₪.
A20: שבט בנימין / אסף תאגיד השידור | B20: 30206.25 | C20: 30750 | D20: 19635 | E20: =SUMIF('עובדים זרים - ספטמבר'!$A$9:$A$58,"אסף תאגיד השידור",'עובדים זרים - ספטמבר'!$H$9:$H$58) -> 6545 | F20: =E20-D20 -> -13090 | G20: ירידה של 13,090 ₪. מ-2 עובדים ל-1: Praveen רשום רק אצל "ארי שבט בנימין". nagendra בוטל באמצע החודש - 85 שעות מול 216.
A21: דוד קבלן / NH Clinics | B21: 8550 | C21: 18050 | D21: 0 | E21: =SUMIF('עובדים זרים - ספטמבר'!$A$9:$A$58,"דוד בן חמו קבלן",'עובדים זרים - ספטמבר'!$H$9:$H$58) -> 0 | F21: =E21-D21 -> 0 | G21: אין פעילות גם בספטמבר.
A22: גרשון | B22: 16940 | C22: 16170 | D22: 0 | E22: =SUMIF('עובדים זרים - ספטמבר'!$A$9:$A$58,"גרשון",'עובדים זרים - ספטמבר'!$H$9:$H$58) -> 0 | F22: =E22-D22 -> 0 | G22: אין פעילות גם בספטמבר.
A23: נריה קידוח הצפון | B23: 6080 | C23: 13920 | D23: 0 | E23: =SUMIF('עובדים זרים - ספטמבר'!$A$9:$A$58,"נריה קידוח הצפון",'עובדים זרים - ספטמבר'!$H$9:$H$58) -> 0 | F23: =E23-D23 -> 0 | G23: אין פעילות גם בספטמבר.
A24: אליעזר הקר אלומיניום | B24: 0 | C24: 8550 | D24: 56057.5 | E24: =SUMIF('עובדים זרים - ספטמבר'!$A$9:$A$58,"אליעזר הקר אלומיניום",'עובדים זרים - ספטמבר'!$H$9:$H$58) -> 70775 | F24: =E24-D24 -> 14717.5 | G24: עלייה של 14,718 ₪ (+26%) - הלקוח היחיד שעלה. עדיין 4 עובדים אבל בהרכב אחר: temurbek עבד חודש מלא (182.5 שעות מול 44), SAMANDAR (בניסיון, 50 ₪) כבר לא, ו-sanat עבר אליו מברגשטיין ב-3 לחודש (148.5 שעות). השעות עלו מ-600.5 ל-745, וכל השעות בתעריף 95 ₪.
A25: שי רם חברה לבנייה | B25: 0 | C25: 6930 | D25: 16093 | E25: =SUMIF('עובדים זרים - ספטמבר'!$A$9:$A$58,"שי רם חברה לבנייה",'עובדים זרים - ספטמבר'!$H$9:$H$58) -> 13898.5 | F25: =E25-D25 -> -2194.5 | G25: ירידה של 2,195 ₪ (-14%). אותו עובד (narendra), 180.5 שעות מול 209. התעריף קבוע 77 ₪.
A26: ארי שבט בנימין | B26: 0 | C26: 0 | D26: 21175 | E26: =SUMIF('עובדים זרים - ספטמבר'!$A$9:$A$58,"ארי שבט בנימין",'עובדים זרים - ספטמבר'!$H$9:$H$58) -> 16247 | F26: =E26-D26 -> -4928 | G26: ירידה של 4,928 ₪ (-23%). אותם 2 עובדים (sri ram, Praveen), אבל שניהם בוטלו באמצע החודש - 105.5 שעות כל אחד, 211 מול 275.
A27: מאי מערכות חשמל | B27: 0 | C27: 0 | D27: 10741.5 | E27: =SUMIF('עובדים זרים - ספטמבר'!$A$9:$A$58,"מאי מערכות חשמל",'עובדים זרים - ספטמבר'!$H$9:$H$58) -> 0 | F27: =E27-D27 -> -10741.5 | G27: אין פעילות בספטמבר. welikala לא מופיע בקובץ השעות של ספטמבר.
A28: סה"כ | B28: =SUM(B12:B27) -> 707644.75 | C28: =SUM(C12:C27) -> 971024.5 | D28: =SUM(D12:D27) -> 1047144.5 | E28: =SUM(E12:E27) -> 682461.5 | F28: =SUM(F12:F27) -> -364683
A30: דירות ושירותי קרקע | B30: יוני 2026 | C30: יולי 2026 | D30: אוגוסט 2026 | E30: ספטמבר 2026 | F30: שינוי (₪) | G30: שינוי (%)
A31: הכנסה (פנימי + חיצוני) | B31: ='דירות - יוני'!E14 -> 98165 | C31: ='דירות - שירותי קרקע'!E15 -> 116489.99 | D31: ='דירות - אוגוסט'!E15 -> 112497.79 | E31: ='דירות - ספטמבר'!E15 -> 101149.99 | F31: =E31-D31 -> -11347.8 | G31: =E31/D31-1 -> -0.10087131
A32: עלות (שכירות + שוטפות + עמלות) | B32: ='דירות - יוני'!I14 -> 65800 | C32: ='דירות - שירותי קרקע'!I15 -> 76120 | D32: ='דירות - אוגוסט'!I15 -> 74920 | E32: ='דירות - ספטמבר'!I15 -> 74320 | F32: =E32-D32 -> -600 | G32: =E32/D32-1 -> -0.0080085424
A33: רווח | B33: =B31-B32 -> 32365 | C33: =C31-C32 -> 40369.99 | D33: =D31-D32 -> 37577.79 | E33: =E31-E32 -> 26829.99 | F33: =E33-D33 -> -10747.8 | G33: =E33/D33-1 -> -0.28601469
A35: שורה תחתונה | B35: יוני 2026 | C35: יולי 2026 | D35: אוגוסט 2026 | E35: ספטמבר 2026 | F35: שינוי (₪) | G35: שינוי (%)
A36: רווח גולמי מאוחד | B36: =B8+B33 -> 149529.75 | C36: =C8+C33 -> 215843.24 | D36: =D8+D33 -> 203556.29 | E36: =E8+E33 -> 139455.99 | F36: =E36-D36 -> -64100.3 | G36: =E36/D36-1 -> -0.31490208
A37: עמלות (שלמה + רועי + לעובדים) | B37: ='סיכום מאוחד'!B93+'סיכום מאוחד'!B94 -> 9626 | C37: ='סיכום מאוחד'!C93+'סיכום מאוחד'!C94 -> 8326 | D37: ='סיכום מאוחד'!D93+'סיכום מאוחד'!D94+'עובדים זרים - אוגוסט'!M68 -> 15070 | E37: ='סיכום מאוחד'!E93+'סיכום מאוחד'!E94+'סיכום מאוחד'!E96+'עובדים זרים - ספטמבר'!M59 -> 17114 | F37: =E37-D37 -> 2044 | G37: =E37/D37-1 -> 0.13563371
