Workbook

Sheet סיכום
A1: פרויקט נווה יעקב – סיכום הכנסות, הוצאות ורווח
A2: מזמין | B2: רימון בדאען (ע"י בית ירושלמי)
A3: מחיר | B3: 600 ₪ למ"ר · גליפים 700 ₪ למטר
A4: תאריך התחלה | B4: 11/01/2025
A5: מקור | B5: גיליון "נווה יעקב" בקובץ שהועלה 15/10/2026 · כל הסכומים לא כוללים מע"מ
A7: סעיף | B7: סכום (₪) | C7: % מההכנסות
A8: 💰 סה"כ הכנסות (10 תקבולים) | B8: =הכנסות!C15 -> 1524369.9 | C8: =1 -> 1
A10: הוצאות לפי קטגוריה
A11: קבלן מבצע – חאדר | B11: =הוצאות!D13 -> 636119 | C11: =IF($B$8=0,0,B11/$B$8) -> 0.41729962
A12: יבוא HPL – 3 מכולות | B12: =הוצאות!D20 -> 379096.45 | C12: =IF($B$8=0,0,B12/$B$8) -> 0.24869058
A13: קונסטרוקציה / ברגים / ברקטים / פרופילים | B13: =הוצאות!D28 -> 45928.32 | C13: =IF($B$8=0,0,B13/$B$8) -> 0.030129379
A14: הוצאות כלליות | B14: =הוצאות!D46 -> 24420 | C14: =IF($B$8=0,0,B14/$B$8) -> 0.016019733
A15: הובלות | B15: =הוצאות!D53 -> 11917 | C15: =IF($B$8=0,0,B15/$B$8) -> 0.0078176561
A16: מהנדס ושונות | B16: =הוצאות!D58 -> 12889 | C16: =IF($B$8=0,0,B16/$B$8) -> 0.0084552966
A17: 📤 סה"כ הוצאות | B17: =SUM(B11:B16) -> 1110369.8 | C17: =IF($B$8=0,0,B17/$B$8) -> 0.72841227
A19: ✅ רווח הפרויקט עד היום | B19: =B8-B17 -> 414000.17 | C19: =IF($B$8=0,0,B19/$B$8) -> 0.27158773
A21: לפי החוזה
A22: חוזה: 2,400 מ"ר × 600 ₪ | B22: =2400*600 -> 1440000
A23: בפועל: 3,000 מ"ר × 600 ₪ (לפי הגיליון) | B23: =3000*600 -> 1800000
A24: ⏳ יתרה לגבייה לפי 3,000 מ"ר (ללא גליפים) | B24: =B23-B8 -> 275630.06 | C24: לפני מע"מ
A26: ⚠️ שאלות פתוחות
A27: מורט: בגיליון יש "סך הכל 10,089" (2,950$) ושורה נוספת של 3,409.28 (תואמת לתשלום של מטה ל-MURAT ב-05/10). כאן נספר רק 10,089, בהנחה שה-3,409.28 הוא חלק מהסכום הזה. אם זה תשלום נוסף - הרווח יורד ב-3,409.28.
A28: גור את שיפר - חשבונית אחת בלי סכום ("?") - לא נספרה.
A29: גרייטדור הובלה 7,197 - מסומן "לקזז בסוף מחאדר". אם יקוזז מהתשלום לחאדר, ההוצאה לא משתנה (רק עוברת מקטגוריה לקטגוריה).
A30: חאדר - "מזומן לפני פסח" 95,000 הוא תשלום במזומן; שאר הסכומים לפי חשבוניות. בגיליון "הכנסות . הוצאות שאין שיוך" יש גם "סדין קאפ חיפ" 10,000 (18/03) + 6,520 (20/03) "תשלום חאדר בית ירושלמי" - לוודא שאינם תוספת ל-20,000 של סדין קאק.
A31: גליפים (700 ₪ למטר) - אין נתון על כמות, לכן לא נכללו ביתרה לגבייה.
A32: בידוד מרפסת רוטנברג 99,716 - עבר דרכנו ובית ירושלמי החזיר, לכן לא נכלל (מופיע בנפרד בתחתית גיליון "הוצאות"). ⚠️ ההחזר מבית ירושלמי לא צריך להופיע ב-10 התקבולים - אם הוא נכלל שם, יש להוריד אותו מההכנסות.
A33: בגיליון "סיכום" של הקובץ המקורי נווה יעקב עדיין מופיע עם נתונים ישנים: הכנסות 1,104,121 / הוצאות 725,687 / רווח 378,434.

Sheet הכנסות
A1: פרויקט נווה יעקב – הכנסות (תקבולים מהמזמין)
A2: מזמין: רימון בדאען ע"י בית ירושלמי · הסכומים לא כוללים מע"מ (כפי שבגיליון המקור; ×1.18 = הסכום שהתקבל בפועל)
A4: # | B4: תאריך | C4: סכום לפני מע"מ (₪) | D4: כולל מע"מ (₪) | E4: הערות
A5: 1 | B5: 20/01/2026 | C5: 202389.83 | D5: =ROUND(C5*1.18,2) -> 238820
A6: 2 | B6: 17/02/2026 | C6: 83000 | D6: =ROUND(C6*1.18,2) -> 97940
A7: 3 | B7: 16/03/2026 | C7: 30000 | D7: =ROUND(C7*1.18,2) -> 35400
A8: 4 | B8: 31/03/2026 | C8: 300000 | D8: =ROUND(C8*1.18,2) -> 354000
A9: 5 | B9: 23/04/2026 | C9: 35580.13 | D9: =ROUND(C9*1.18,2) -> 41984.55
A10: 6 | B10: 18/05/2026 | C10: 224579.66 | D10: =ROUND(C10*1.18,2) -> 265004
A11: 7 | B11: 25/06/2026 | C11: 228575.42 | D11: =ROUND(C11*1.18,2) -> 269719
A12: 8 | B12: 10/08/2026 | C12: 95735.59 | D12: =ROUND(C12*1.18,2) -> 112968 | E12: ✅ תואם לבנק מטה 10/08: העברת זה"ב בית ירושלמי 112,968
A13: 9 | B13: 20/08/2026 | C13: 197390.67 | D13: =ROUND(C13*1.18,2) -> 232920.99
A14: 10 | B14: 29/09/2026 | C14: 127118.64 | D14: =ROUND(C14*1.18,2) -> 150000
A15: סה"כ הכנסות | C15: =SUM(C5:C14) -> 1524369.9 | D15: =SUM(D5:D14) -> 1798756.5

Sheet הוצאות
A1: פרויקט נווה יעקב – הוצאות לפי קטגוריה (לא כולל מע"מ)
A3: קטגוריה | B3: ספק / תיאור | C3: תאריך | D3: סכום (₪) | E3: סכום ($) | F3: הערות / מקור
A4: קבלן מבצע – חאדר
A5: קבלן מבצע – חאדר | B5: חאדר – סדין קאק | C5: 20/03/2026 | D5: 20000
A6: קבלן מבצע – חאדר | B6: חאדר | C6: 20/04/2026 | D6: 24700
A7: קבלן מבצע – חאדר | B7: חאדר – מזומן לפני פסח | D7: 95000 | F7: מזומן
A8: קבלן מבצע – חאדר | B8: חאדר (ראם משלוחים) | C8: 28/06/2026 | D8: 140000 | F8: חאדר.pdf
A9: קבלן מבצע – חאדר | B9: חאדר (ראם משלוחים) | C9: 19/07/2026 | D9: 141353 | F9: 91013_invoice.pdf
A10: קבלן מבצע – חאדר | B10: חאדר (משי ניהול עובדים) | C10: 23/08/2026 | D10: 125758
A11: קבלן מבצע – חאדר | B11: חאדר (משי ניהול עובדים) | D11: 87308
A12: קבלן מבצע – חאדר | B12: נדב איטומים | D12: 2000 | F12: הודעה מיום 28.04
A13: סה"כ קבלן מבצע – חאדר | D13: =SUM(D5:D12) -> 636119
A15: יבוא HPL – 3 מכולות
A16: יבוא HPL – 3 מכולות | B16: מכולה 1 – 384.61 מ"ר | D16: 39063 | E16: 10942 | F16: Shipment 1 – Commercial Invoice
A17: יבוא HPL – 3 מכולות | B17: מכולה 2 – 991.25 מ"ר | D17: 99831 | E17: 28201 | F17: Shipment 2 – Commercial Invoice
A18: יבוא HPL – 3 מכולות | B18: מכולה 3 – 1,487.4 מ"ר | D18: 235648 | E18: 68106.41 | F18: Shipment 3 – Commercial Invoice
A19: יבוא HPL – 3 מכולות | B19: עלות מט"ח לפי 3 מכולות | D19: 4554.45
A20: סה"כ יבוא HPL – 3 מכולות | D20: =SUM(D16:D19) -> 379096.45
A22: קונסטרוקציה / ברגים / ברקטים / פרופילים
A23: קונסטרוקציה / ברגים / ברקטים / פרופילים | B23: גור את שיפר | D23: 12735.59 | F23: SI266002349
A24: קונסטרוקציה / ברגים / ברקטים / פרופילים | B24: גור את שיפר | D24: 5249 | F24: SI266003946
A25: קונסטרוקציה / ברגים / ברקטים / פרופילים | B25: גור את שיפר | D25: 18823.73
A26: קונסטרוקציה / ברגים / ברקטים / פרופילים | B26: פרופילים DB (מילי סויסה) | C26: 03/08/2026 | D26: 9120 | F26: ✅ תואם לבנק מטה 03/08: 10,761.60 כולל מע"מ
A27: קונסטרוקציה / ברגים / ברקטים / פרופילים | B27: גור את שיפר – חשבונית נוספת | F27: ⚠️ סכום לא מולא בגיליון המקור ("?")
A28: סה"כ קונסטרוקציה / ברגים / ברקטים / פרופילים | D28: =SUM(D23:D27) -> 45928.32
A30: הוצאות כלליות
A31: הוצאות כלליות | B31: ברגים | D31: 1455
A32: הוצאות כלליות | B32: ברגים | D32: 1508
A33: הוצאות כלליות | B33: הדפסת תוכניות | D33: 161
A34: הוצאות כלליות | B34: אלקטרו סליל | D34: 392
A35: הוצאות כלליות | B35: גאלה | D35: 975
A36: הוצאות כלליות | B36: ארפק | D36: 2763
A37: הוצאות כלליות | B37: גאלה | D37: 1239
A38: הוצאות כלליות | B38: גאלה קלאסיק | D38: 2000
A39: הוצאות כלליות | B39: אלקטרו סליל | D39: 180
A40: הוצאות כלליות | B40: גאלה קלאסיק – ברגים | C40: 14/06/2026 | D40: 1659
A41: הוצאות כלליות | B41: ארפק די | D41: 1160 | F41: 210012492
A42: הוצאות כלליות | B42: ארפק | D42: 1160 | F42: 210012573 · העברה
A43: הוצאות כלליות | B43: רוטנברג – ספריי קצף | D43: 2808
A44: הוצאות כלליות | B44: ארפק | D44: 4640 | F44: 210012671 · העברה
...
